Workbook

Sheet Master Modelo
A1: PRODUTO | B1: NCM | C1: ALIQ. II | D1: ALIQ. IPI | E1: ALIQ PIS | F1: ALIQ. COFINS | G1: DESCRICAO | H1: PESO./UNIT | I1: PREÇO UNIT. | J1: Dumping/Kg | K1: Cubagem/Unit | N1: FOB SEM DESCONTO | O1: MINIMO | P1: MEDIO
L2: =I2/H2 -> #DIV/0! | N2: 7.48
L3: =I3/H3 -> #DIV/0! | N3: 7.48
L4: =I4/H4 -> #DIV/0! | N4: 1.8
L5: =I5/H5 -> #DIV/0! | N5: 1.8
L6: =I6/H6 -> #DIV/0! | N6: 4.24
L7: =I7/H7 -> #DIV/0! | N7: 4.24
L8: =I8/H8 -> #DIV/0! | N8: 4.07
L9: =I9/H9 -> #DIV/0! | N9: 4.24
L10: =I10/H10 -> #DIV/0! | N10: 0.98
L11: =I11/H11 -> #DIV/0! | N11: 3.6
L12: =I12/H12 -> #DIV/0! | N12: 3.6
L13: =I13/H13 -> #DIV/0! | N13: 2.33
... L19: =I19/H19 -> #DIV/0! | N19: 2.8

Sheet Produtos
A1: PRODUTO | B1: DESCRIÇÃO | C1: NCM | E1: VALOR UNITÁRIO | F1: PESO UNITÁRIO | G1: CUBAGEM UNITARIA | H1: PREÇO POR KG | I1: II | J1: PIS | K1: COFINS | L1: Dumping | M1: IPI | N1: ICMS ESTADO DESTINO | O1: MVA AJUSTADO | P1: PESO TOTAL | Q1: CUBAGEM TOTAL | R1: VALOR FOB | S1: FRETE INTERNACIONAL/PESO | T1: FRETE INTERNACIONAL/CUBAGEM | U1: CAPATAZIA/PESO | V1: CAPATAZIA/CUBAGEM | W1: VALOR ADUANEIRO: | X1: SISCOMEX | Y1: MARINHA MERCANTE | Z1: OUTRAS DESP. ADUANEIRAS | AA1: DESPESAS ADUANEIRAS: | AB1: II | AC1: PIS | AD1: COFINS | AE1: IPI | AF1: Dumping | AG1: ICMS | AH1: IMPOSTOS NACIONALIZAÇÃO: | AI1: DESPESAS OPERACIONAIS: | AJ1: VARIAÇÃO CAMBIAL | AK1: CUSTO TOTAL DA OPERAÇÃO: | AL1: CRÉDITO PIS | AM1: CRÉDITO COFINS | AN1: CRÉDITO IPI | AO1: CRÉDITO ICMS | AP1: CUSTO DE ESTOQUE | AQ1: CUSTO TRADING | AR1: DÉBITO PIS | AS1: DÉBITO COFINS | AT1: DÉBITO ICMS | AU1: VALOR SEM IPI | AV1: IPI DESTACADO | AW1: NOTA FISCAL DE SAÍDA: | AX1: DESC. COMERCIAL | AY1: VALOR A PAGAR | AZ1: LUCRO BRUTO OPERAÇÃO | BA1: IR | BB1: CSLL | BC1: LUCRO LIQUIDO | BD1: =IF('Entrada e Saida'!$H$11="TRADING","Valor Venda Unit. C/IPI","Custo C/IPI") -> Valor Venda Unit. C/IPI | BE1: Desconto | BF1: Valor Final C/Desc. | BG1: Credito Unit. IPI | BH1: Credito Unit PIS | BI1: Credito Unit. Cofins | BJ1: Credito Unit. ICMS | BK1: Valor Unit. Sem Impostos | BL1: =IF('Entrada e Saida'!$H$14="P.JURIDICA","VALOR ST", "VALOR DIFAL") -> VALOR ST | BM1: =IF('Entrada e Saida'!$H$14="P.JURIDICA","Valor Final C/Desc.+IPI+ST","Valor Final C/Desc.+IPI+DIFAL") -> Valor Final C/Desc.+IPI+ST
B2: =VLOOKUP(A2,'Master Modelo'!A:I,7,FALSE) -> #N/A | C2: =VLOOKUP(A2,'Master Modelo'!A:I,2,FALSE) -> #N/A | E2: =VLOOKUP(A2,'Master Modelo'!A:I,9,FALSE) -> #N/A | F2: =IFERROR(VLOOKUP(A2,'Master Modelo'!A:I,8,FALSE),0) -> 0 | G2: =IFERROR(VLOOKUP(A2,'Master Modelo'!A:K,11,FALSE),0) -> 0 | H2: =(D2*E2)/(D2*F2) -> #N/A | I2: =VLOOKUP(A2,'Master Modelo'!A:I,3,FALSE) -> #N/A | J2: =VLOOKUP(A2,'Master Modelo'!A:I,5,FALSE) -> #N/A | K2: =VLOOKUP(A2,'Master Modelo'!A:I,6,FALSE) -> #N/A | L2: =VLOOKUP(A2,'Master Modelo'!A:J,10,FALSE) -> #N/A | M2: =VLOOKUP(A2,'Master Modelo'!A:I,4,FALSE) -> #N/A | P2: =D2*F2 -> 0 | Q2: =D2*G2 -> 0 | R2: =D2*E2*'Entrada e Saida'!$K$8 -> #N/A | S2: ='Entrada e Saida'!$H$21*'Entrada e Saida'!$K$8*(P2/(SUM(P:P))) -> #DIV/0! | T2: ='Entrada e Saida'!$H$21*'Entrada e Saida'!$K$8*(Q2/(SUM(Q:Q))) -> #DIV/0! | U2: ='Entrada e Saida'!$H$22*(P2/(SUM(P:P))) -> #DIV/0! | V2: ='Entrada e Saida'!$H$22*(Q2/(SUM(Q:Q))) -> #DIV/0! | W2: =R2+S2+U2 -> #N/A | X2: ='Entrada e Saida'!$H$26*(IF('Entrada e Saida'!$H$15="PESO",(P2/(SUM(P:P))),(Q2/(SUM(Q:Q))))) -> #DIV/0! | Y2: ='Entrada e Saida'!$H$27*(IF('Entrada e Saida'!$H$15="PESO",(P2/(SUM(P:P))),(Q2/(SUM(Q:Q))))) -> #DIV/0! | Z2: ='Entrada e Saida'!$H$28*(IF('Entrada e Saida'!$H$15="PESO",(P2/(SUM(P:P))),(Q2/(SUM(Q:Q))))) -> #DIV/0! | AA2: =X2+Y2+Z2 -> #DIV/0! | AB2: =W2*I2 -> #N/A | AC2: =W2*J2 -> #N/A | AD2: =W2*K2 -> #N/A | AE2: =(W2+AB2)*M2 -> #N/A | AF2: =IFERROR(D2*F2*L2*'Entrada e Saida'!$K$8,0) -> 0 | AG2: =((W2+AA2+AB2+AC2+AD2+AE2+AF2)/(1-'Entrada e Saida'!$G$65))*'Entrada e Saida'!$I$66 -> #N/A | AH2: =SUM(AB2:AG2) -> #N/A | AI2: ='Entrada e Saida'!$K$51*(IF('Entrada e Saida'!$H$15="PESO",(P2/(SUM(P:P))),(Q2/(SUM(Q:Q))))) -> #DIV/0! | AJ2: =(('Entrada e Saida'!$K$10-'Entrada e Saida'!$K$8)*E2*D2) -> #N/A | AK2: =IF('Entrada e Saida'!$H$15="PESO",W2+AA2+AH2+AI2+AJ2,W2+AA2+AH2+AI2+AJ2-S2+T2-U2+V2) -> #N/A | AL2: =IF('Entrada e Saida'!$H$12="REAL",AC2,0) -> #N/A | AM2: =IF('Entrada e Saida'!$H$12="REAL",AD2,0) -> #N/A | AN2: =IF('Entrada e Saida'!$H$13= "NÃO",AE2,0) -> #N/A | AO2: =AG2 -> #N/A | AP2: =AK2-SUM(AL2:AO2) -> #N/A | AQ2: =IF('Entrada e Saida'!$H$11="TRADING",AU2*'Custo Resumido'!D2,0) -> #N/A | AR2: =IF('Entrada e Saida'!$H$11="TRADING",AU2*'Entrada e Saida'!$G$63,0) -> #N/A | AS2: =IF('Entrada e Saida'!$H$11="TRADING",AU2*'Entrada e Saida'!$G$64,0) -> #N/A | AT2: =IF('Entrada e Saida'!$H$11="TRADING",AU2*'Entrada e Saida'!$G$65,0) -> #N/A | AU2: =IF('Entrada e Saida'!$H$11="TRADING",AP2/(1-(SUM('Entrada e Saida'!$G$63:$G$65)+'Custo Resumido'!D2)),0) -> #N/A | AV2: =IF('Entrada e Saida'!$H$13="NÃO",AU2*M2,0) -> #N/A | AW2: =AU2+AV2 -> #N/A | AX2: ='Entrada e Saida'!$G$74*AU2 -> #N/A | AY2: =AW2-AX2 -> #N/A | AZ2: =AQ2+('Entrada e Saida'!$G$65-'Entrada e Saida'!$I$65)*AU2-AX2 -> #N/A | BA2: =IF('Entrada e Saida'!$H$12="REAL",AZ2*'Entrada e Saida'!$G$81,AU2*'Entrada e Saida'!$G$81) -> #N/A | BB2: =IF('Entrada e Saida'!$H$12="REAL",AZ2*'Entrada e Saida'!$G$82,AU2*'Entrada e Saida'!$G$82) -> #N/A | BC2: =AZ2-BA2-BB2 -> #N/A | BD2: =IF('Entrada e Saida'!$H$11="TRADING",AW2/D2,AK2/D2) -> #N/A | BE2: =AX2/D2 -> #N/A | BF2: =BD2-BE2 -> #N/A | BG2: =IF('Entrada e Saida'!$H$11="TRADING",AV2/D2,AN2/D2) -> #N/A | BH2: =IF('Entrada e Saida'!$H$11="TRADING",IF('Entrada e Saida'!$H$12="REAL",AR2/D2,0),AL2/D2) -> #N/A | BI2: =IF('Entrada e Saida'!$H$11="TRADING",IF('Entrada e Saida'!$H$12="REAL",AS2/D2,0),AM2/D2) -> #N/A | BJ2: =IF('Entrada e Saida'!$H$11="TRADING",AT2/D2,AO2/D2) -> #N/A | BK2: =BF2-SUM(BG2:BJ2) -> #N/A | BL2: =IF(O2>0,IFERROR(IF('Entrada e Saida'!$H$11="DIRETA",0,(IF('Entrada e Saida'!$H$14="P.JURIDICA",(BD2*(1+O2)*N2)-((BD2/(1+M2))*'Entrada e Saida'!$G$65),((Produtos!N2-'Entrada e Saida'!$G$65)*Produtos!BD2)))),0),0) -> 0 | BM2: =BF2+BL2 -> #N/A
B3: =VLOOKUP(A3,'Master Modelo'!A:I,7,FALSE) -> #N/A | C3: =VLOOKUP(A3,'Master Modelo'!A:I,2,FALSE) -> #N/A | E3: =IFERROR(VLOOKUP(A3,'Master Modelo'!A:I,9,FALSE),0) -> 0 | F3: =IFERROR(VLOOKUP(A3,'Master Modelo'!A:I,8,FALSE),0) -> 0 | G3: =IFERROR(VLOOKUP(A3,'Master Modelo'!A:K,11,FALSE),0) -> 0 | H3: =(D3*E3)/(D3*F3) -> #DIV/0! | I3: =IFERROR(VLOOKUP(A3,'Master Modelo'!A:I,3,FALSE),0) -> 0 | J3: =IFERROR(VLOOKUP(A3,'Master Modelo'!A:I,5,FALSE),0) -> 0 | K3: =IFERROR(VLOOKUP(A3,'Master Modelo'!A:I,6,FALSE),0) -> 0 | L3: =VLOOKUP(A3,'Master Modelo'!A:J,10,FALSE) -> #N/A | M3: =IFERROR(VLOOKUP(A3,'Master Modelo'!A:I,4,FALSE),0) -> 0 | P3: =D3*F3 -> 0 | Q3: =D3*G3 -> 0 | R3: =D3*E3*'Entrada e Saida'!$K$8 -> 0 | S3: ='Entrada e Saida'!$H$21*'Entrada e Saida'!$K$8*(P3/(SUM(P:P))) -> #DIV/0! | T3: ='Entrada e Saida'!$H$21*'Entrada e Saida'!$K$8*(Q3/(SUM(Q:Q))) -> #DIV/0! | U3: ='Entrada e Saida'!$H$22*(P3/(SUM(P:P))) -> #DIV/0! | V3: ='Entrada e Saida'!$H$22*(Q3/(SUM(Q:Q))) -> #DIV/0! | W3: =R3+S3+U3 -> #DIV/0! | X3: ='Entrada e Saida'!$H$26*(IF('Entrada e Saida'!$H$15="PESO",(P3/(SUM(P:P))),(Q3/(SUM(Q:Q))))) -> #DIV/0! | Y3: ='Entrada e Saida'!$H$27*(IF('Entrada e Saida'!$H$15="PESO",(P3/(SUM(P:P))),(Q3/(SUM(Q:Q))))) -> #DIV/0! | Z3: ='Entrada e Saida'!$H$28*(IF('Entrada e Saida'!$H$15="PESO",(P3/(SUM(P:P))),(Q3/(SUM(Q:Q))))) -> #DIV/0! | AA3: =X3+Y3+Z3 -> #DIV/0! | AB3: =W3*I3 -> #DIV/0! | AC3: =W3*J3 -> #DIV/0! | AD3: =W3*K3 -> #DIV/0! | AE3: =(W3+AB3)*M3 -> #DIV/0! | AF3: =IFERROR(D3*F3*L3*'Entrada e Saida'!$K$8,0) -> 0 | AG3: =((W3+AA3+AB3+AC3+AD3+AE3+AF3)/(1-'Entrada e Saida'!$G$65))*'Entrada e Saida'!$I$66 -> #DIV/0! | AH3: =SUM(AB3:AG3) -> #DIV/0! | AI3: ='Entrada e Saida'!$K$51*(IF('Entrada e Saida'!$H$15="PESO",(P3/(SUM(P:P))),(Q3/(SUM(Q:Q))))) -> #DIV/0! | AJ3: =(('Entrada e Saida'!$K$10-'Entrada e Saida'!$K$8)*E3*D3) -> 0 | AK3: =IF('Entrada e Saida'!$H$15="PESO",W3+AA3+AH3+AI3+AJ3,W3+AA3+AH3+AI3+AJ3-S3+T3-U3+V3) -> #DIV/0! | AL3: =IF('Entrada e Saida'!$H$12="REAL",AC3,0) -> #DIV/0! | AM3: =IF('Entrada e Saida'!$H$12="REAL",AD3,0) -> #DIV/0! | AN3: =IF('Entrada e Saida'!$H$13= "NÃO",AE3,0) -> #DIV/0! | AO3: =AG3 -> #DIV/0! | AP3: =AK3-SUM(AL3:AO3) -> #DIV/0! | AQ3: =IF('Entrada e Saida'!$H$11="TRADING",AU3*'Custo Resumido'!D3,0) -> #DIV/0! | AR3: =IF('Entrada e Saida'!$H$11="TRADING",AU3*'Entrada e Saida'!$G$63,0) -> #DIV/0! | AS3: =IF('Entrada e Saida'!$H$11="TRADING",AU3*'Entrada e Saida'!$G$64,0) -> #DIV/0! | AT3: =IF('Entrada e Saida'!$H$11="TRADING",AU3*'Entrada e Saida'!$G$65,0) -> #DIV/0! | AU3: =IF('Entrada e Saida'!$H$11="TRADING",AP3/(1-(SUM('Entrada e Saida'!$G$63:$G$65)+'Custo Resumido'!D3)),0) -> #DIV/0! | AV3: =IF('Entrada e Saida'!$H$13="NÃO",AU3*M3,0) -> #DIV/0! | AW3: =AU3+AV3 -> #DIV/0! | AX3: ='Entrada e Saida'!$G$74*AU3 -> #DIV/0! | AY3: =AW3-AX3 -> #DIV/0! | AZ3: =AQ3+('Entrada e Saida'!$G$65-'Entrada e Saida'!$I$65)*AU3-AX3 -> #DIV/0! | BA3: =IF('Entrada e Saida'!$H$12="REAL",AZ3*'Entrada e Saida'!$G$81,AU3*'Entrada e Saida'!$G$81) -> #DIV/0! | BB3: =IF('Entrada e Saida'!$H$12="REAL",AZ3*'Entrada e Saida'!$G$82,AU3*'Entrada e Saida'!$G$82) -> #DIV/0! | BC3: =AZ3-BA3-BB3 -> #DIV/0! | BD3: =IF('Entrada e Saida'!$H$11="TRADING",AW3/D3,AK3/D3) -> #DIV/0! | BE3: =AX3/D3 -> #DIV/0! | BF3: =BD3-BE3 -> #DIV/0! | BG3: =IF('Entrada e Saida'!$H$11="TRADING",AV3/D3,AN3/D3) -> #DIV/0! | BH3: =IF('Entrada e Saida'!$H$11="TRADING",IF('Entrada e Saida'!$H$12="REAL",AR3/D3,0),AL3/D3) -> #DIV/0! | BI3: =IF('Entrada e Saida'!$H$11="TRADING",IF('Entrada e Saida'!$H$12="REAL",AS3/D3,0),AM3/D3) -> #DIV/0! | BJ3: =IF('Entrada e Saida'!$H$11="TRADING",AT3/D3,AO3/D3) -> #DIV/0! | BK3: =BF3-SUM(BG3:BJ3) -> #DIV/0! | BL3: =IF(O3>0,IFERROR(IF('Entrada e Saida'!$H$11="DIRETA",0,(IF('Entrada e Saida'!$H$14="P.JURIDICA",(BD3*(1+O3)*N3)-((BD3/(1+M3))*'Entrada e Saida'!$G$65),((Produtos!N3-'Entrada e Saida'!$G$65)*Produtos!BD3)))),0),0) -> 0 | BM3: =BF3+BL3 -> #DIV/0!
B4: =VLOOKUP(A4,'Master Modelo'!A:I,7,FALSE) -> #N/A | C4: =VLOOKUP(A4,'Master Modelo'!A:I,2,FALSE) -> #N/A | E4: =IFERROR(VLOOKUP(A4,'Master Modelo'!A:I,9,FALSE),0) -> 0 | F4: =IFERROR(VLOOKUP(A4,'Master Modelo'!A:I,8,FALSE),0) -> 0 | G4: =IFERROR(VLOOKUP(A4,'Master Modelo'!A:K,11,FALSE),0) -> 0 | H4: =(D4*E4)/(D4*F4) -> #DIV/0! | I4: =IFERROR(VLOOKUP(A4,'Master Modelo'!A:I,3,FALSE),0) -> 0 | J4: =IFERROR(VLOOKUP(A4,'Master Modelo'!A:I,5,FALSE),0) -> 0 | K4: =IFERROR(VLOOKUP(A4,'Master Modelo'!A:I,6,FALSE),0) -> 0 | L4: =VLOOKUP(A4,'Master Modelo'!A:J,10,FALSE) -> #N/A | M4: =IFERROR(VLOOKUP(A4,'Master Modelo'!A:I,4,FALSE),0) -> 0 | P4: =D4*F4 -> 0 | Q4: =D4*G4 -> 0 | R4: =D4*E4*'Entrada e Saida'!$K$8 -> 0 | S4: ='Entrada e Saida'!$H$21*'Entrada e Saida'!$K$8*(P4/(SUM(P:P))) -> #DIV/0! | T4: ='Entrada e Saida'!$H$21*'Entrada e Saida'!$K$8*(Q4/(SUM(Q:Q))) -> #DIV/0! | U4: ='Entrada e Saida'!$H$22*(P4/(SUM(P:P))) -> #DIV/0! | V4: ='Entrada e Saida'!$H$22*(Q4/(SUM(Q:Q))) -> #DIV/0! | W4: =R4+S4+U4 -> #DIV/0! | X4: ='Entrada e Saida'!$H$26*(IF('Entrada e Saida'!$H$15="PESO",(P4/(SUM(P:P))),(Q4/(SUM(Q:Q))))) -> #DIV/0! | Y4: ='Entrada e Saida'!$H$27*(IF('Entrada e Saida'!$H$15="PESO",(P4/(SUM(P:P))),(Q4/(SUM(Q:Q))))) -> #DIV/0! | Z4: ='Entrada e Saida'!$H$28*(IF('Entrada e Saida'!$H$15="PESO",(P4/(SUM(P:P))),(Q4/(SUM(Q:Q))))) -> #DIV/0! | AA4: =X4+Y4+Z4 -> #DIV/0! | AB4: =W4*I4 -> #DIV/0! | AC4: =W4*J4 -> #DIV/0! | AD4: =W4*K4 -> #DIV/0! | AE4: =(W4+AB4)*M4 -> #DIV/0! | AF4: =IFERROR(D4*F4*L4*'Entrada e Saida'!$K$8,0) -> 0 | AG4: =((W4+AA4+AB4+AC4+AD4+AE4+AF4)/(1-'Entrada e Saida'!$G$65))*'Entrada e Saida'!$I$66 -> #DIV/0! | AH4: =SUM(AB4:AG4) -> #DIV/0! | AI4: ='Entrada e Saida'!$K$51*(IF('Entrada e Saida'!$H$15="PESO",(P4/(SUM(P:P))),(Q4/(SUM(Q:Q))))) -> #DIV/0! | AJ4: =(('Entrada e Saida'!$K$10-'Entrada e Saida'!$K$8)*E4*D4) -> 0 | AK4: =IF('Entrada e Saida'!$H$15="PESO",W4+AA4+AH4+AI4+AJ4,W4+AA4+AH4+AI4+AJ4-S4+T4-U4+V4) -> #DIV/0! | AL4: =IF('Entrada e Saida'!$H$12="REAL",AC4,0) -> #DIV/0! | AM4: =IF('Entrada e Saida'!$H$12="REAL",AD4,0) -> #DIV/0! | AN4: =IF('Entrada e Saida'!$H$13= "NÃO",AE4,0) -> #DIV/0! | AO4: =AG4 -> #DIV/0! | AP4: =AK4-SUM(AL4:AO4) -> #DIV/0! | AQ4: =IF('Entrada e Saida'!$H$11="TRADING",AU4*'Custo Resumido'!D4,0) -> #DIV/0! | AR4: =IF('Entrada e Saida'!$H$11="TRADING",AU4*'Entrada e Saida'!$G$63,0) -> #DIV/0! | AS4: =IF('Entrada e Saida'!$H$11="TRADING",AU4*'Entrada e Saida'!$G$64,0) -> #DIV/0! | AT4: =IF('Entrada e Saida'!$H$11="TRADING",AU4*'Entrada e Saida'!$G$65,0) -> #DIV/0! | AU4: =IF('Entrada e Saida'!$H$11="TRADING",AP4/(1-(SUM('Entrada e Saida'!$G$63:$G$65)+'Custo Resumido'!D4)),0) -> #DIV/0! | AV4: =IF('Entrada e Saida'!$H$13="NÃO",AU4*M4,0) -> #DIV/0! | AW4: =AU4+AV4 -> #DIV/0! | AX4: ='Entrada e Saida'!$G$74*AU4 -> #DIV/0! | AY4: =AW4-AX4 -> #DIV/0! | AZ4: =AQ4+('Entrada e Saida'!$G$65-'Entrada e Saida'!$I$65)*AU4-AX4 -> #DIV/0! | BA4: =IF('Entrada e Saida'!$H$12="REAL",AZ4*'Entrada e Saida'!$G$81,AU4*'Entrada e Saida'!$G$81) -> #DIV/0! | BB4: =IF('Entrada e Saida'!$H$12="REAL",AZ4*'Entrada e Saida'!$G$82,AU4*'Entrada e Saida'!$G$82) -> #DIV/0! | BC4: =AZ4-BA4-BB4 -> #DIV/0! | BD4: =IF('Entrada e Saida'!$H$11="TRADING",AW4/D4,AK4/D4) -> #DIV/0! | BE4: =AX4/D4 -> #DIV/0! | BF4: =BD4-BE4 -> #DIV/0! | BG4: =IF('Entrada e Saida'!$H$11="TRADING",AV4/D4,AN4/D4) -> #DIV/0! | BH4: =IF('Entrada e Saida'!$H$11="TRADING",IF('Entrada e Saida'!$H$12="REAL",AR4/D4,0),AL4/D4) -> #DIV/0! | BI4: =IF('Entrada e Saida'!$H$11="TRADING",IF('Entrada e Saida'!$H$12="REAL",AS4/D4,0),AM4/D4) -> #DIV/0! | BJ4: =IF('Entrada e Saida'!$H$11="TRADING",AT4/D4,AO4/D4) -> #DIV/0! | BK4: =BF4-SUM(BG4:BJ4) -> #DIV/0! | BL4: =IF(O4>0,IFERROR(IF('Entrada e Saida'!$H$11="DIRETA",0,(IF('Entrada e Saida'!$H$14="P.JURIDICA",(BD4*(1+O4)*N4)-((BD4/(1+M4))*'Entrada e Saida'!$G$65),((Produtos!N4-'Entrada e Saida'!$G$65)*Produtos!BD4)))),0),0) -> 0 | BM4: =BF4+BL4 -> #DIV/0!
B5: =VLOOKUP(A5,'Master Modelo'!A:I,7,FALSE) -> #N/A | C5: =VLOOKUP(A5,'Master Modelo'!A:I,2,FALSE) -> #N/A | E5: =IFERROR(VLOOKUP(A5,'Master Modelo'!A:I,9,FALSE),0) -> 0 | F5: =IFERROR(VLOOKUP(A5,'Master Modelo'!A:I,8,FALSE),0) -> 0 | G5: =IFERROR(VLOOKUP(A5,'Master Modelo'!A:K,11,FALSE),0) -> 0 | H5: =(D5*E5)/(D5*F5) -> #DIV/0! | I5: =IFERROR(VLOOKUP(A5,'Master Modelo'!A:I,3,FALSE),0) -> 0 | J5: =IFERROR(VLOOKUP(A5,'Master Modelo'!A:I,5,FALSE),0) -> 0 | K5: =IFERROR(VLOOKUP(A5,'Master Modelo'!A:I,6,FALSE),0) -> 0 | L5: =VLOOKUP(A5,'Master Modelo'!A:J,10,FALSE) -> #N/A | M5: =IFERROR(VLOOKUP(A5,'Master Modelo'!A:I,4,FALSE),0) -> 0 | P5: =D5*F5 -> 0 | Q5: =D5*G5 -> 0 | R5: =D5*E5*'Entrada e Saida'!$K$8 -> 0 | S5: ='Entrada e Saida'!$H$21*'Entrada e Saida'!$K$8*(P5/(SUM(P:P))) -> #DIV/0! | T5: ='Entrada e Saida'!$H$21*'Entrada e Saida'!$K$8*(Q5/(SUM(Q:Q))) -> #DIV/0! | U5: ='Entrada e Saida'!$H$22*(P5/(SUM(P:P))) -> #DIV/0! | V5: ='Entrada e Saida'!$H$22*(Q5/(SUM(Q:Q))) -> #DIV/0! | W5: =R5+S5+U5 -> #DIV/0! | X5: ='Entrada e Saida'!$H$26*(IF('Entrada e Saida'!$H$15="PESO",(P5/(SUM(P:P))),(Q5/(SUM(Q:Q))))) -> #DIV/0! | Y5: ='Entrada e Saida'!$H$27*(IF('Entrada e Saida'!$H$15="PESO",(P5/(SUM(P:P))),(Q5/(SUM(Q:Q))))) -> #DIV/0! | Z5: ='Entrada e Saida'!$H$28*(IF('Entrada e Saida'!$H$15="PESO",(P5/(SUM(P:P))),(Q5/(SUM(Q:Q))))) -> #DIV/0! | AA5: =X5+Y5+Z5 -> #DIV/0! | AB5: =W5*I5 -> #DIV/0! | AC5: =W5*J5 -> #DIV/0! | AD5: =W5*K5 -> #DIV/0! | AE5: =(W5+AB5)*M5 -> #DIV/0! | AF5: =IFERROR(D5*F5*L5*'Entrada e Saida'!$K$8,0) -> 0 | AG5: =((W5+AA5+AB5+AC5+AD5+AE5+AF5)/(1-'Entrada e Saida'!$G$65))*'Entrada e Saida'!$I$66 -> #DIV/0! | AH5: =SUM(AB5:AG5) -> #DIV/0! | AI5: ='Entrada e Saida'!$K$51*(IF('Entrada e Saida'!$H$15="PESO",(P5/(SUM(P:P))),(Q5/(SUM(Q:Q))))) -> #DIV/0! | AJ5: =(('Entrada e Saida'!$K$10-'Entrada e Saida'!$K$8)*E5*D5) -> 0 | AK5: =IF('Entrada e Saida'!$H$15="PESO",W5+AA5+AH5+AI5+AJ5,W5+AA5+AH5+AI5+AJ5-S5+T5-U5+V5) -> #DIV/0! | AL5: =IF('Entrada e Saida'!$H$12="REAL",AC5,0) -> #DIV/0! | AM5: =IF('Entrada e Saida'!$H$12="REAL",AD5,0) -> #DIV/0! | AN5: =IF('Entrada e Saida'!$H$13= "NÃO",AE5,0) -> #DIV/0! | AO5: =AG5 -> #DIV/0! | AP5: =AK5-SUM(AL5:AO5) -> #DIV/0! | AQ5: =IF('Entrada e Saida'!$H$11="TRADING",AU5*'Custo Resumido'!D5,0) -> #DIV/0! | AR5: =IF('Entrada e Saida'!$H$11="TRADING",AU5*'Entrada e Saida'!$G$63,0) -> #DIV/0! | AS5: =IF('Entrada e Saida'!$H$11="TRADING",AU5*'Entrada e Saida'!$G$64,0) -> #DIV/0! | AT5: =IF('Entrada e Saida'!$H$11="TRADING",AU5*'Entrada e Saida'!$G$65,0) -> #DIV/0! | AU5: =IF('Entrada e Saida'!$H$11="TRADING",AP5/(1-(SUM('Entrada e Saida'!$G$63:$G$65)+'Custo Resumido'!D5)),0) -> #DIV/0! | AV5: =IF('Entrada e Saida'!$H$13="NÃO",AU5*M5,0) -> #DIV/0! | AW5: =AU5+AV5 -> #DIV/0! | AX5: ='Entrada e Saida'!$G$74*AU5 -> #DIV/0! | AY5: =AW5-AX5 -> #DIV/0! | AZ5: =AQ5+('Entrada e Saida'!$G$65-'Entrada e Saida'!$I$65)*AU5-AX5 -> #DIV/0! | BA5: =IF('Entrada e Saida'!$H$12="REAL",AZ5*'Entrada e Saida'!$G$81,AU5*'Entrada e Saida'!$G$81) -> #DIV/0! | BB5: =IF('Entrada e Saida'!$H$12="REAL",AZ5*'Entrada e Saida'!$G$82,AU5*'Entrada e Saida'!$G$82) -> #DIV/0! | BC5: =AZ5-BA5-BB5 -> #DIV/0! | BD5: =IF('Entrada e Saida'!$H$11="TRADING",AW5/D5,AK5/D5) -> #DIV/0! | BE5: =AX5/D5 -> #DIV/0! | BF5: =BD5-BE5 -> #DIV/0! | BG5: =IF('Entrada e Saida'!$H$11="TRADING",AV5/D5,AN5/D5) -> #DIV/0! | BH5: =IF('Entrada e Saida'!$H$11="TRADING",IF('Entrada e Saida'!$H$12="REAL",AR5/D5,0),AL5/D5) -> #DIV/0! | BI5: =IF('Entrada e Saida'!$H$11="TRADING",IF('Entrada e Saida'!$H$12="REAL",AS5/D5,0),AM5/D5) -> #DIV/0! | BJ5: =IF('Entrada e Saida'!$H$11="TRADING",AT5/D5,AO5/D5) -> #DIV/0! | BK5: =BF5-SUM(BG5:BJ5) -> #DIV/0! | BL5: =IF(O5>0,IFERROR(IF('Entrada e Saida'!$H$11="DIRETA",0,(IF('Entrada e Saida'!$H$14="P.JURIDICA",(BD5*(1+O5)*N5)-((BD5/(1+M5))*'Entrada e Saida'!$G$65),((Produtos!N5-'Entrada e Saida'!$G$65)*Produtos!BD5)))),0),0) -> 0 | BM5: =BF5+BL5 -> #DIV/0!
B6: =VLOOKUP(A6,'Master Modelo'!A:I,7,FALSE) -> #N/A | C6: =VLOOKUP(A6,'Master Modelo'!A:I,2,FALSE) -> #N/A | E6: =IFERROR(VLOOKUP(A6,'Master Modelo'!A:I,9,FALSE),0) -> 0 | F6: =IFERROR(VLOOKUP(A6,'Master Modelo'!A:I,8,FALSE),0) -> 0 | G6: =IFERROR(VLOOKUP(A6,'Master Modelo'!A:K,11,FALSE),0) -> 0 | H6: =(D6*E6)/(D6*F6) -> #DIV/0! | I6: =IFERROR(VLOOKUP(A6,'Master Modelo'!A:I,3,FALSE),0) -> 0 | J6: =IFERROR(VLOOKUP(A6,'Master Modelo'!A:I,5,FALSE),0) -> 0 | K6: =IFERROR(VLOOKUP(A6,'Master Modelo'!A:I,6,FALSE),0) -> 0 | L6: =VLOOKUP(A6,'Master Modelo'!A:J,10,FALSE) -> #N/A | M6: =IFERROR(VLOOKUP(A6,'Master Modelo'!A:I,4,FALSE),0) -> 0 | P6: =D6*F6 -> 0 | Q6: =D6*G6 -> 0 | R6: =D6*E6*'Entrada e Saida'!$K$8 -> 0 | S6: ='Entrada e Saida'!$H$21*'Entrada e Saida'!$K$8*(P6/(SUM(P:P))) -> #DIV/0! | T6: ='Entrada e Saida'!$H$21*'Entrada e Saida'!$K$8*(Q6/(SUM(Q:Q))) -> #DIV/0! | U6: ='Entrada e Saida'!$H$22*(P6/(SUM(P:P))) -> #DIV/0! | V6: ='Entrada e Saida'!$H$22*(Q6/(SUM(Q:Q))) -> #DIV/0! | W6: =R6+S6+U6 -> #DIV/0! | X6: ='Entrada e Saida'!$H$26*(IF('Entrada e Saida'!$H$15="PESO",(P6/(SUM(P:P))),(Q6/(SUM(Q:Q))))) -> #DIV/0! | Y6: ='Entrada e Saida'!$H$27*(IF('Entrada e Saida'!$H$15="PESO",(P6/(SUM(P:P))),(Q6/(SUM(Q:Q))))) -> #DIV/0! | Z6: ='Entrada e Saida'!$H$28*(IF('Entrada e Saida'!$H$15="PESO",(P6/(SUM(P:P))),(Q6/(SUM(Q:Q))))) -> #DIV/0! | AA6: =X6+Y6+Z6 -> #DIV/0! | AB6: =W6*I6 -> #DIV/0! | AC6: =W6*J6 -> #DIV/0! | AD6: =W6*K6 -> #DIV/0! | AE6: =(W6+AB6)*M6 -> #DIV/0! | AF6: =IFERROR(D6*F6*L6*'Entrada e Saida'!$K$8,0) -> 0 | AG6: =((W6+AA6+AB6+AC6+AD6+AE6+AF6)/(1-'Entrada e Saida'!$G$65))*'Entrada e Saida'!$I$66 -> #DIV/0! | AH6: =SUM(AB6:AG6) -> #DIV/0! | AI6: ='Entrada e Saida'!$K$51*(IF('Entrada e Saida'!$H$15="PESO",(P6/(SUM(P:P))),(Q6/(SUM(Q:Q))))) -> #DIV/0! | AJ6: =(('Entrada e Saida'!$K$10-'Entrada e Saida'!$K$8)*E6*D6) -> 0 | AK6: =IF('Entrada e Saida'!$H$15="PESO",W6+AA6+AH6+AI6+AJ6,W6+AA6+AH6+AI6+AJ6-S6+T6-U6+V6) -> #DIV/0! | AL6: =IF('Entrada e Saida'!$H$12="REAL",AC6,0) -> #DIV/0! | AM6: =IF('Entrada e Saida'!$H$12="REAL",AD6,0) -> #DIV/0! | AN6: =IF('Entrada e Saida'!$H$13= "NÃO",AE6,0) -> #DIV/0! | AO6: =AG6 -> #DIV/0! | AP6: =AK6-SUM(AL6:AO6) -> #DIV/0! | AQ6: =IF('Entrada e Saida'!$H$11="TRADING",AU6*'Custo Resumido'!D6,0) -> #DIV/0! | AR6: =IF('Entrada e Saida'!$H$11="TRADING",AU6*'Entrada e Saida'!$G$63,0) -> #DIV/0! | AS6: =IF('Entrada e Saida'!$H$11="TRADING",AU6*'Entrada e Saida'!$G$64,0) -> #DIV/0! | AT6: =IF('Entrada e Saida'!$H$11="TRADING",AU6*'Entrada e Saida'!$G$65,0) -> #DIV/0! | AU6: =IF('Entrada e Saida'!$H$11="TRADING",AP6/(1-(SUM('Entrada e Saida'!$G$63:$G$65)+'Custo Resumido'!D6)),0) -> #DIV/0! | AV6: =IF('Entrada e Saida'!$H$13="NÃO",AU6*M6,0) -> #DIV/0! | AW6: =AU6+AV6 -> #DIV/0! | AX6: ='Entrada e Saida'!$G$74*AU6 -> #DIV/0! | AY6: =AW6-AX6 -> #DIV/0! | AZ6: =AQ6+('Entrada e Saida'!$G$65-'Entrada e Saida'!$I$65)*AU6-AX6 -> #DIV/0! | BA6: =IF('Entrada e Saida'!$H$12="REAL",AZ6*'Entrada e Saida'!$G$81,AU6*'Entrada e Saida'!$G$81) -> #DIV/0! | BB6: =IF('Entrada e Saida'!$H$12="REAL",AZ6*'Entrada e Saida'!$G$82,AU6*'Entrada e Saida'!$G$82) -> #DIV/0! | BC6: =AZ6-BA6-BB6 -> #DIV/0! | BD6: =IF('Entrada e Saida'!$H$11="TRADING",AW6/D6,AK6/D6) -> #DIV/0! | BE6: =AX6/D6 -> #DIV/0! | BF6: =BD6-BE6 -> #DIV/0! | BG6: =IF('Entrada e Saida'!$H$11="TRADING",AV6/D6,AN6/D6) -> #DIV/0! | BH6: =IF('Entrada e Saida'!$H$11="TRADING",IF('Entrada e Saida'!$H$12="REAL",AR6/D6,0),AL6/D6) -> #DIV/0! | BI6: =IF('Entrada e Saida'!$H$11="TRADING",IF('Entrada e Saida'!$H$12="REAL",AS6/D6,0),AM6/D6) -> #DIV/0! | BJ6: =IF('Entrada e Saida'!$H$11="TRADING",AT6/D6,AO6/D6) -> #DIV/0! | BK6: =BF6-SUM(BG6:BJ6) -> #DIV/0! | BL6: =IF(O6>0,IFERROR(IF('Entrada e Saida'!$H$11="DIRETA",0,(IF('Entrada e Saida'!$H$14="P.JURIDICA",(BD6*(1+O6)*N6)-((BD6/(1+M6))*'Entrada e Saida'!$G$65),((Produtos!N6-'Entrada e Saida'!$G$65)*Produtos!BD6)))),0),0) -> 0 | BM6: =BF6+BL6 -> #DIV/0!
B7: =VLOOKUP(A7,'Master Modelo'!A:I,7,FALSE) -> #N/A | C7: =VLOOKUP(A7,'Master Modelo'!A:I,2,FALSE) -> #N/A | E7: =IFERROR(VLOOKUP(A7,'Master Modelo'!A:I,9,FALSE),0) -> 0 | F7: =IFERROR(VLOOKUP(A7,'Master Modelo'!A:I,8,FALSE),0) -> 0 | G7: =IFERROR(VLOOKUP(A7,'Master Modelo'!A:K,11,FALSE),0) -> 0 | H7: =(D7*E7)/(D7*F7) -> #DIV/0! | I7: =IFERROR(VLOOKUP(A7,'Master Modelo'!A:I,3,FALSE),0) -> 0 | J7: =IFERROR(VLOOKUP(A7,'Master Modelo'!A:I,5,FALSE),0) -> 0 | K7: =IFERROR(VLOOKUP(A7,'Master Modelo'!A:I,6,FALSE),0) -> 0 | L7: =VLOOKUP(A7,'Master Modelo'!A:J,10,FALSE) -> #N/A | M7: =IFERROR(VLOOKUP(A7,'Master Modelo'!A:I,4,FALSE),0) -> 0 | P7: =D7*F7 -> 0 | Q7: =D7*G7 -> 0 | R7: =D7*E7*'Entrada e Saida'!$K$8 -> 0 | S7: ='Entrada e Saida'!$H$21*'Entrada e Saida'!$K$8*(P7/(SUM(P:P))) -> #DIV/0! | T7: ='Entrada e Saida'!$H$21*'Entrada e Saida'!$K$8*(Q7/(SUM(Q:Q))) -> #DIV/0! | U7: ='Entrada e Saida'!$H$22*(P7/(SUM(P:P))) -> #DIV/0! | V7: ='Entrada e Saida'!$H$22*(Q7/(SUM(Q:Q))) -> #DIV/0! | W7: =R7+S7+U7 -> #DIV/0! | X7: ='Entrada e Saida'!$H$26*(IF('Entrada e Saida'!$H$15="PESO",(P7/(SUM(P:P))),(Q7/(SUM(Q:Q))))) -> #DIV/0! | Y7: ='Entrada e Saida'!$H$27*(IF('Entrada e Saida'!$H$15="PESO",(P7/(SUM(P:P))),(Q7/(SUM(Q:Q))))) -> #DIV/0! | Z7: ='Entrada e Saida'!$H$28*(IF('Entrada e Saida'!$H$15="PESO",(P7/(SUM(P:P))),(Q7/(SUM(Q:Q))))) -> #DIV/0! | AA7: =X7+Y7+Z7 -> #DIV/0! | AB7: =W7*I7 -> #DIV/0! | AC7: =W7*J7 -> #DIV/0! | AD7: =W7*K7 -> #DIV/0! | AE7: =(W7+AB7)*M7 -> #DIV/0! | AF7: =IFERROR(D7*F7*L7*'Entrada e Saida'!$K$8,0) -> 0 | AG7: =((W7+AA7+AB7+AC7+AD7+AE7+AF7)/(1-'Entrada e Saida'!$G$65))*'Entrada e Saida'!$I$66 -> #DIV/0! | AH7: =SUM(AB7:AG7) -> #DIV/0! | AI7: ='Entrada e Saida'!$K$51*(IF('Entrada e Saida'!$H$15="PESO",(P7/(SUM(P:P))),(Q7/(SUM(Q:Q))))) -> #DIV/0! | AJ7: =(('Entrada e Saida'!$K$10-'Entrada e Saida'!$K$8)*E7*D7) -> 0 | AK7: =IF('Entrada e Saida'!$H$15="PESO",W7+AA7+AH7+AI7+AJ7,W7+AA7+AH7+AI7+AJ7-S7+T7-U7+V7) -> #DIV/0! | AL7: =IF('Entrada e Saida'!$H$12="REAL",AC7,0) -> #DIV/0! | AM7: =IF('Entrada e Saida'!$H$12="REAL",AD7,0) -> #DIV/0! | AN7: =IF('Entrada e Saida'!$H$13= "NÃO",AE7,0) -> #DIV/0! | AO7: =AG7 -> #DIV/0! | AP7: =AK7-SUM(AL7:AO7) -> #DIV/0! | AQ7: =IF('Entrada e Saida'!$H$11="TRADING",AU7*'Custo Resumido'!D7,0) -> #DIV/0! | AR7: =IF('Entrada e Saida'!$H$11="TRADING",AU7*'Entrada e Saida'!$G$63,0) -> #DIV/0! | AS7: =IF('Entrada e Saida'!$H$11="TRADING",AU7*'Entrada e Saida'!$G$64,0) -> #DIV/0! | AT7: =IF('Entrada e Saida'!$H$11="TRADING",AU7*'Entrada e Saida'!$G$65,0) -> #DIV/0! | AU7: =IF('Entrada e Saida'!$H$11="TRADING",AP7/(1-(SUM('Entrada e Saida'!$G$63:$G$65)+'Custo Resumido'!D7)),0) -> #DIV/0! | AV7: =IF('Entrada e Saida'!$H$13="NÃO",AU7*M7,0) -> #DIV/0! | AW7: =AU7+AV7 -> #DIV/0! | AX7: ='Entrada e Saida'!$G$74*AU7 -> #DIV/0! | AY7: =AW7-AX7 -> #DIV/0! | AZ7: =AQ7+('Entrada e Saida'!$G$65-'Entrada e Saida'!$I$65)*AU7-AX7 -> #DIV/0! | BA7: =IF('Entrada e Saida'!$H$12="REAL",AZ7*'Entrada e Saida'!$G$81,AU7*'Entrada e Saida'!$G$81) -> #DIV/0! | BB7: =IF('Entrada e Saida'!$H$12="REAL",AZ7*'Entrada e Saida'!$G$82,AU7*'Entrada e Saida'!$G$82) -> #DIV/0! | BC7: =AZ7-BA7-BB7 -> #DIV/0! | BD7: =IF('Entrada e Saida'!$H$11="TRADING",AW7/D7,AK7/D7) -> #DIV/0! | BE7: =AX7/D7 -> #DIV/0! | BF7: =BD7-BE7 -> #DIV/0! | BG7: =IF('Entrada e Saida'!$H$11="TRADING",AV7/D7,AN7/D7) -> #DIV/0! | BH7: =IF('Entrada e Saida'!$H$11="TRADING",IF('Entrada e Saida'!$H$12="REAL",AR7/D7,0),AL7/D7) -> #DIV/0! | BI7: =IF('Entrada e Saida'!$H$11="TRADING",IF('Entrada e Saida'!$H$12="REAL",AS7/D7,0),AM7/D7) -> #DIV/0! | BJ7: =IF('Entrada e Saida'!$H$11="TRADING",AT7/D7,AO7/D7) -> #DIV/0! | BK7: =BF7-SUM(BG7:BJ7) -> #DIV/0! | BL7: =IF(O7>0,IFERROR(IF('Entrada e Saida'!$H$11="DIRETA",0,(IF('Entrada e Saida'!$H$14="P.JURIDICA",(BD7*(1+O7)*N7)-((BD7/(1+M7))*'Entrada e Saida'!$G$65),((Produtos!N7-'Entrada e Saida'!$G$65)*Produtos!BD7)))),0),0) -> 0 | BM7: =BF7+BL7 -> #DIV/0!
B8: =VLOOKUP(A8,'Master Modelo'!A:I,7,FALSE) -> #N/A | C8: =VLOOKUP(A8,'Master Modelo'!A:I,2,FALSE) -> #N/A | E8: =IFERROR(VLOOKUP(A8,'Master Modelo'!A:I,9,FALSE),0) -> 0 | F8: =IFERROR(VLOOKUP(A8,'Master Modelo'!A:I,8,FALSE),0) -> 0 | G8: =IFERROR(VLOOKUP(A8,'Master Modelo'!A:K,11,FALSE),0) -> 0 | H8: =(D8*E8)/(D8*F8) -> #DIV/0! | I8: =IFERROR(VLOOKUP(A8,'Master Modelo'!A:I,3,FALSE),0) -> 0 | J8: =IFERROR(VLOOKUP(A8,'Master Modelo'!A:I,5,FALSE),0) -> 0 | K8: =IFERROR(VLOOKUP(A8,'Master Modelo'!A:I,6,FALSE),0) -> 0 | L8: =VLOOKUP(A8,'Master Modelo'!A:J,10,FALSE) -> #N/A | M8: =IFERROR(VLOOKUP(A8,'Master Modelo'!A:I,4,FALSE),0) -> 0 | P8: =D8*F8 -> 0 | Q8: =D8*G8 -> 0 | R8: =D8*E8*'Entrada e Saida'!$K$8 -> 0 | S8: ='Entrada e Saida'!$H$21*'Entrada e Saida'!$K$8*(P8/(SUM(P:P))) -> #DIV/0! | T8: ='Entrada e Saida'!$H$21*'Entrada e Saida'!$K$8*(Q8/(SUM(Q:Q))) -> #DIV/0! | U8: ='Entrada e Saida'!$H$22*(P8/(SUM(P:P))) -> #DIV/0! | V8: ='Entrada e Saida'!$H$22*(Q8/(SUM(Q:Q))) -> #DIV/0! | W8: =R8+S8+U8 -> #DIV/0! | X8: ='Entrada e Saida'!$H$26*(IF('Entrada e Saida'!$H$15="PESO",(P8/(SUM(P:P))),(Q8/(SUM(Q:Q))))) -> #DIV/0! | Y8: ='Entrada e Saida'!$H$27*(IF('Entrada e Saida'!$H$15="PESO",(P8/(SUM(P:P))),(Q8/(SUM(Q:Q))))) -> #DIV/0! | Z8: ='Entrada e Saida'!$H$28*(IF('Entrada e Saida'!$H$15="PESO",(P8/(SUM(P:P))),(Q8/(SUM(Q:Q))))) -> #DIV/0! | AA8: =X8+Y8+Z8 -> #DIV/0! | AB8: =W8*I8 -> #DIV/0! | AC8: =W8*J8 -> #DIV/0! | AD8: =W8*K8 -> #DIV/0! | AE8: =(W8+AB8)*M8 -> #DIV/0! | AF8: =IFERROR(D8*F8*L8*'Entrada e Saida'!$K$8,0) -> 0 | AG8: =((W8+AA8+AB8+AC8+AD8+AE8+AF8)/(1-'Entrada e Saida'!$G$65))*'Entrada e Saida'!$I$66 -> #DIV/0! | AH8: =SUM(AB8:AG8) -> #DIV/0! | AI8: ='Entrada e Saida'!$K$51*(IF('Entrada e Saida'!$H$15="PESO",(P8/(SUM(P:P))),(Q8/(SUM(Q:Q))))) -> #DIV/0! | AJ8: =(('Entrada e Saida'!$K$10-'Entrada e Saida'!$K$8)*E8*D8) -> 0 | AK8: =IF('Entrada e Saida'!$H$15="PESO",W8+AA8+AH8+AI8+AJ8,W8+AA8+AH8+AI8+AJ8-S8+T8-U8+V8) -> #DIV/0! | AL8: =IF('Entrada e Saida'!$H$12="REAL",AC8,0) -> #DIV/0! | AM8: =IF('Entrada e Saida'!$H$12="REAL",AD8,0) -> #DIV/0! | AN8: =IF('Entrada e Saida'!$H$13= "NÃO",AE8,0) -> #DIV/0! | AO8: =AG8 -> #DIV/0! | AP8: =AK8-SUM(AL8:AO8) -> #DIV/0! | AQ8: =IF('Entrada e Saida'!$H$11="TRADING",AU8*'Custo Resumido'!D8,0) -> #DIV/0! | AR8: =IF('Entrada e Saida'!$H$11="TRADING",AU8*'Entrada e Saida'!$G$63,0) -> #DIV/0! | AS8: =IF('Entrada e Saida'!$H$11="TRADING",AU8*'Entrada e Saida'!$G$64,0) -> #DIV/0! | AT8: =IF('Entrada e Saida'!$H$11="TRADING",AU8*'Entrada e Saida'!$G$65,0) -> #DIV/0! | AU8: =IF('Entrada e Saida'!$H$11="TRADING",AP8/(1-(SUM('Entrada e Saida'!$G$63:$G$65)+'Custo Resumido'!D8)),0) -> #DIV/0! | AV8: =IF('Entrada e Saida'!$H$13="NÃO",AU8*M8,0) -> #DIV/0! | AW8: =AU8+AV8 -> #DIV/0! | AX8: ='Entrada e Saida'!$G$74*AU8 -> #DIV/0! | AY8: =AW8-AX8 -> #DIV/0! | AZ8: =AQ8+('Entrada e Saida'!$G$65-'Entrada e Saida'!$I$65)*AU8-AX8 -> #DIV/0! | BA8: =IF('Entrada e Saida'!$H$12="REAL",AZ8*'Entrada e Saida'!$G$81,AU8*'Entrada e Saida'!$G$81) -> #DIV/0! | BB8: =IF('Entrada e Saida'!$H$12="REAL",AZ8*'Entrada e Saida'!$G$82,AU8*'Entrada e Saida'!$G$82) -> #DIV/0! | BC8: =AZ8-BA8-BB8 -> #DIV/0! | BD8: =IF('Entrada e Saida'!$H$11="TRADING",AW8/D8,AK8/D8) -> #DIV/0! | BE8: =AX8/D8 -> #DIV/0! | BF8: =BD8-BE8 -> #DIV/0! | BG8: =IF('Entrada e Saida'!$H$11="TRADING",AV8/D8,AN8/D8) -> #DIV/0! | BH8: =IF('Entrada e Saida'!$H$11="TRADING",IF('Entrada e Saida'!$H$12="REAL",AR8/D8,0),AL8/D8) -> #DIV/0! | BI8: =IF('Entrada e Saida'!$H$11="TRADING",IF('Entrada e Saida'!$H$12="REAL",AS8/D8,0),AM8/D8) -> #DIV/0! | BJ8: =IF('Entrada e Saida'!$H$11="TRADING",AT8/D8,AO8/D8) -> #DIV/0! | BK8: =BF8-SUM(BG8:BJ8) -> #DIV/0! | BL8: =IF(O8>0,IFERROR(IF('Entrada e Saida'!$H$11="DIRETA",0,(IF('Entrada e Saida'!$H$14="P.JURIDICA",(BD8*(1+O8)*N8)-((BD8/(1+M8))*'Entrada e Saida'!$G$65),((Produtos!N8-'Entrada e Saida'!$G$65)*Produtos!BD8)))),0),0) -> 0 | BM8: =BF8+BL8 -> #DIV/0!
B9: =VLOOKUP(A9,'Master Modelo'!A:I,7,FALSE) -> #N/A | C9: =VLOOKUP(A9,'Master Modelo'!A:I,2,FALSE) -> #N/A | E9: =IFERROR(VLOOKUP(A9,'Master Modelo'!A:I,9,FALSE),0) -> 0 | F9: =IFERROR(VLOOKUP(A9,'Master Modelo'!A:I,8,FALSE),0) -> 0 | G9: =IFERROR(VLOOKUP(A9,'Master Modelo'!A:K,11,FALSE),0) -> 0 | H9: =(D9*E9)/(D9*F9) -> #DIV/0! | I9: =IFERROR(VLOOKUP(A9,'Master Modelo'!A:I,3,FALSE),0) -> 0 | J9: =IFERROR(VLOOKUP(A9,'Master Modelo'!A:I,5,FALSE),0) -> 0 | K9: =IFERROR(VLOOKUP(A9,'Master Modelo'!A:I,6,FALSE),0) -> 0 | L9: =VLOOKUP(A9,'Master Modelo'!A:J,10,FALSE) -> #N/A | M9: =IFERROR(VLOOKUP(A9,'Master Modelo'!A:I,4,FALSE),0) -> 0 | P9: =D9*F9 -> 0 | Q9: =D9*G9 -> 0 | R9: =D9*E9*'Entrada e Saida'!$K$8 -> 0 | S9: ='Entrada e Saida'!$H$21*'Entrada e Saida'!$K$8*(P9/(SUM(P:P))) -> #DIV/0! | T9: ='Entrada e Saida'!$H$21*'Entrada e Saida'!$K$8*(Q9/(SUM(Q:Q))) -> #DIV/0! | U9: ='Entrada e Saida'!$H$22*(P9/(SUM(P:P))) -> #DIV/0! | V9: ='Entrada e Saida'!$H$22*(Q9/(SUM(Q:Q))) -> #DIV/0! | W9: =R9+S9+U9 -> #DIV/0! | X9: ='Entrada e Saida'!$H$26*(IF('Entrada e Saida'!$H$15="PESO",(P9/(SUM(P:P))),(Q9/(SUM(Q:Q))))) -> #DIV/0! | Y9: ='Entrada e Saida'!$H$27*(IF('Entrada e Saida'!$H$15="PESO",(P9/(SUM(P:P))),(Q9/(SUM(Q:Q))))) -> #DIV/0! | Z9: ='Entrada e Saida'!$H$28*(IF('Entrada e Saida'!$H$15="PESO",(P9/(SUM(P:P))),(Q9/(SUM(Q:Q))))) -> #DIV/0! | AA9: =X9+Y9+Z9 -> #DIV/0! | AB9: =W9*I9 -> #DIV/0! | AC9: =W9*J9 -> #DIV/0! | AD9: =W9*K9 -> #DIV/0! | AE9: =(W9+AB9)*M9 -> #DIV/0! | AF9: =IFERROR(D9*F9*L9*'Entrada e Saida'!$K$8,0) -> 0 | AG9: =((W9+AA9+AB9+AC9+AD9+AE9+AF9)/(1-'Entrada e Saida'!$G$65))*'Entrada e Saida'!$I$66 -> #DIV/0! | AH9: =SUM(AB9:AG9) -> #DIV/0! | AI9: ='Entrada e Saida'!$K$51*(IF('Entrada e Saida'!$H$15="PESO",(P9/(SUM(P:P))),(Q9/(SUM(Q:Q))))) -> #DIV/0! | AJ9: =(('Entrada e Saida'!$K$10-'Entrada e Saida'!$K$8)*E9*D9) -> 0 | AK9: =IF('Entrada e Saida'!$H$15="PESO",W9+AA9+AH9+AI9+AJ9,W9+AA9+AH9+AI9+AJ9-S9+T9-U9+V9) -> #DIV/0! | AL9: =IF('Entrada e Saida'!$H$12="REAL",AC9,0) -> #DIV/0! | AM9: =IF('Entrada e Saida'!$H$12="REAL",AD9,0) -> #DIV/0! | AN9: =IF('Entrada e Saida'!$H$13= "NÃO",AE9,0) -> #DIV/0! | AO9: =AG9 -> #DIV/0! | AP9: =AK9-SUM(AL9:AO9) -> #DIV/0! | AQ9: =IF('Entrada e Saida'!$H$11="TRADING",AU9*'Custo Resumido'!D9,0) -> #DIV/0! | AR9: =IF('Entrada e Saida'!$H$11="TRADING",AU9*'Entrada e Saida'!$G$63,0) -> #DIV/0! | AS9: =IF('Entrada e Saida'!$H$11="TRADING",AU9*'Entrada e Saida'!$G$64,0) -> #DIV/0! | AT9: =IF('Entrada e Saida'!$H$11="TRADING",AU9*'Entrada e Saida'!$G$65,0) -> #DIV/0! | AU9: =IF('Entrada e Saida'!$H$11="TRADING",AP9/(1-(SUM('Entrada e Saida'!$G$63:$G$65)+'Custo Resumido'!D9)),0) -> #DIV/0! | AV9: =IF('Entrada e Saida'!$H$13="NÃO",AU9*M9,0) -> #DIV/0! | AW9: =AU9+AV9 -> #DIV/0! | AX9: ='Entrada e Saida'!$G$74*AU9 -> #DIV/0! | AY9: =AW9-AX9 -> #DIV/0! | AZ9: =AQ9+('Entrada e Saida'!$G$65-'Entrada e Saida'!$I$65)*AU9-AX9 -> #DIV/0! | BA9: =IF('Entrada e Saida'!$H$12="REAL",AZ9*'Entrada e Saida'!$G$81,AU9*'Entrada e Saida'!$G$81) -> #DIV/0! | BB9: =IF('Entrada e Saida'!$H$12="REAL",AZ9*'Entrada e Saida'!$G$82,AU9*'Entrada e Saida'!$G$82) -> #DIV/0! | BC9: =AZ9-BA9-BB9 -> #DIV/0! | BD9: =IF('Entrada e Saida'!$H$11="TRADING",AW9/D9,AK9/D9) -> #DIV/0! | BE9: =AX9/D9 -> #DIV/0! | BF9: =BD9-BE9 -> #DIV/0! | BG9: =IF('Entrada e Saida'!$H$11="TRADING",AV9/D9,AN9/D9) -> #DIV/0! | BH9: =IF('Entrada e Saida'!$H$11="TRADING",IF('Entrada e Saida'!$H$12="REAL",AR9/D9,0),AL9/D9) -> #DIV/0! | BI9: =IF('Entrada e Saida'!$H$11="TRADING",IF('Entrada e Saida'!$H$12="REAL",AS9/D9,0),AM9/D9) -> #DIV/0! | BJ9: =IF('Entrada e Saida'!$H$11="TRADING",AT9/D9,AO9/D9) -> #DIV/0! | BK9: =BF9-SUM(BG9:BJ9) -> #DIV/0! | BL9: =IF(O9>0,IFERROR(IF('Entrada e Saida'!$H$11="DIRETA",0,(IF('Entrada e Saida'!$H$14="P.JURIDICA",(BD9*(1+O9)*N9)-((BD9/(1+M9))*'Entrada e Saida'!$G$65),((Produtos!N9-'Entrada e Saida'!$G$65)*Produtos!BD9)))),0),0) -> 0 | BM9: =BF9+BL9 -> #DIV/0!
B10: =VLOOKUP(A10,'Master Modelo'!A:I,7,FALSE) -> #N/A | C10: =VLOOKUP(A10,'Master Modelo'!A:I,2,FALSE) -> #N/A | E10: =IFERROR(VLOOKUP(A10,'Master Modelo'!A:I,9,FALSE),0) -> 0 | F10: =IFERROR(VLOOKUP(A10,'Master Modelo'!A:I,8,FALSE),0) -> 0 | G10: =IFERROR(VLOOKUP(A10,'Master Modelo'!A:K,11,FALSE),0) -> 0 | H10: =(D10*E10)/(D10*F10) -> #DIV/0! | I10: =IFERROR(VLOOKUP(A10,'Master Modelo'!A:I,3,FALSE),0) -> 0 | J10: =IFERROR(VLOOKUP(A10,'Master Modelo'!A:I,5,FALSE),0) -> 0 | K10: =IFERROR(VLOOKUP(A10,'Master Modelo'!A:I,6,FALSE),0) -> 0 | L10: =VLOOKUP(A10,'Master Modelo'!A:J,10,FALSE) -> #N/A | M10: =IFERROR(VLOOKUP(A10,'Master Modelo'!A:I,4,FALSE),0) -> 0 | P10: =D10*F10 -> 0 | Q10: =D10*G10 -> 0 | R10: =D10*E10*'Entrada e Saida'!$K$8 -> 0 | S10: ='Entrada e Saida'!$H$21*'Entrada e Saida'!$K$8*(P10/(SUM(P:P))) -> #DIV/0! | T10: ='Entrada e Saida'!$H$21*'Entrada e Saida'!$K$8*(Q10/(SUM(Q:Q))) -> #DIV/0! | U10: ='Entrada e Saida'!$H$22*(P10/(SUM(P:P))) -> #DIV/0! | V10: ='Entrada e Saida'!$H$22*(Q10/(SUM(Q:Q))) -> #DIV/0! | W10: =R10+S10+U10 -> #DIV/0! | X10: ='Entrada e Saida'!$H$26*(IF('Entrada e Saida'!$H$15="PESO",(P10/(SUM(P:P))),(Q10/(SUM(Q:Q))))) -> #DIV/0! | Y10: ='Entrada e Saida'!$H$27*(IF('Entrada e Saida'!$H$15="PESO",(P10/(SUM(P:P))),(Q10/(SUM(Q:Q))))) -> #DIV/0! | Z10: ='Entrada e Saida'!$H$28*(IF('Entrada e Saida'!$H$15="PESO",(P10/(SUM(P:P))),(Q10/(SUM(Q:Q))))) -> #DIV/0! | AA10: =X10+Y10+Z10 -> #DIV/0! | AB10: =W10*I10 -> #DIV/0! | AC10: =W10*J10 -> #DIV/0! | AD10: =W10*K10 -> #DIV/0! | AE10: =(W10+AB10)*M10 -> #DIV/0! | AF10: =IFERROR(D10*F10*L10*'Entrada e Saida'!$K$8,0) -> 0 | AG10: =((W10+AA10+AB10+AC10+AD10+AE10+AF10)/(1-'Entrada e Saida'!$G$65))*'Entrada e Saida'!$I$66 -> #DIV/0! | AH10: =SUM(AB10:AG10) -> #DIV/0! | AI10: ='Entrada e Saida'!$K$51*(IF('Entrada e Saida'!$H$15="PESO",(P10/(SUM(P:P))),(Q10/(SUM(Q:Q))))) -> #DIV/0! | AJ10: =(('Entrada e Saida'!$K$10-'Entrada e Saida'!$K$8)*E10*D10) -> 0 | AK10: =IF('Entrada e Saida'!$H$15="PESO",W10+AA10+AH10+AI10+AJ10,W10+AA10+AH10+AI10+AJ10-S10+T10-U10+V10) -> #DIV/0! | AL10: =IF('Entrada e Saida'!$H$12="REAL",AC10,0) -> #DIV/0! | AM10: =IF('Entrada e Saida'!$H$12="REAL",AD10,0) -> #DIV/0! | AN10: =IF('Entrada e Saida'!$H$13= "NÃO",AE10,0) -> #DIV/0! | AO10: =AG10 -> #DIV/0! | AP10: =AK10-SUM(AL10:AO10) -> #DIV/0! | AQ10: =IF('Entrada e Saida'!$H$11="TRADING",AU10*'Custo Resumido'!D10,0) -> #DIV/0! | AR10: =IF('Entrada e Saida'!$H$11="TRADING",AU10*'Entrada e Saida'!$G$63,0) -> #DIV/0! | AS10: =IF('Entrada e Saida'!$H$11="TRADING",AU10*'Entrada e Saida'!$G$64,0) -> #DIV/0! | AT10: =IF('Entrada e Saida'!$H$11="TRADING",AU10*'Entrada e Saida'!$G$65,0) -> #DIV/0! | AU10: =IF('Entrada e Saida'!$H$11="TRADING",AP10/(1-(SUM('Entrada e Saida'!$G$63:$G$65)+'Custo Resumido'!D10)),0) -> #DIV/0! | AV10: =IF('Entrada e Saida'!$H$13="NÃO",AU10*M10,0) -> #DIV/0! | AW10: =AU10+AV10 -> #DIV/0! | AX10: ='Entrada e Saida'!$G$74*AU10 -> #DIV/0! | AY10: =AW10-AX10 -> #DIV/0! | AZ10: =AQ10+('Entrada e Saida'!$G$65-'Entrada e Saida'!$I$65)*AU10-AX10 -> #DIV/0! | BA10: =IF('Entrada e Saida'!$H$12="REAL",AZ10*'Entrada e Saida'!$G$81,AU10*'Entrada e Saida'!$G$81) -> #DIV/0! | BB10: =IF('Entrada e Saida'!$H$12="REAL",AZ10*'Entrada e Saida'!$G$82,AU10*'Entrada e Saida'!$G$82) -> #DIV/0! | BC10: =AZ10-BA10-BB10 -> #DIV/0! | BD10: =IF('Entrada e Saida'!$H$11="TRADING",AW10/D10,AK10/D10) -> #DIV/0! | BE10: =AX10/D10 -> #DIV/0! | BF10: =BD10-BE10 -> #DIV/0! | BG10: =IF('Entrada e Saida'!$H$11="TRADING",AV10/D10,AN10/D10) -> #DIV/0! | BH10: =IF('Entrada e Saida'!$H$11="TRADING",IF('Entrada e Saida'!$H$12="REAL",AR10/D10,0),AL10/D10) -> #DIV/0! | BI10: =IF('Entrada e Saida'!$H$11="TRADING",IF('Entrada e Saida'!$H$12="REAL",AS10/D10,0),AM10/D10) -> #DIV/0! | BJ10: =IF('Entrada e Saida'!$H$11="TRADING",AT10/D10,AO10/D10) -> #DIV/0! | BK10: =BF10-SUM(BG10:BJ10) -> #DIV/0! | BL10: =IF(O10>0,IFERROR(IF('Entrada e Saida'!$H$11="DIRETA",0,(IF('Entrada e Saida'!$H$14="P.JURIDICA",(BD10*(1+O10)*N10)-((BD10/(1+M10))*'Entrada e Saida'!$G$65),((Produtos!N10-'Entrada e Saida'!$G$65)*Produtos!BD10)))),0),0) -> 0 | BM10: =BF10+BL10 -> #DIV/0!
B11: =VLOOKUP(A11,'Master Modelo'!A:I,7,FALSE) -> #N/A | C11: =VLOOKUP(A11,'Master Modelo'!A:I,2,FALSE) -> #N/A | E11: =IFERROR(VLOOKUP(A11,'Master Modelo'!A:I,9,FALSE),0) -> 0 | F11: =IFERROR(VLOOKUP(A11,'Master Modelo'!A:I,8,FALSE),0) -> 0 | G11: =IFERROR(VLOOKUP(A11,'Master Modelo'!A:K,11,FALSE),0) -> 0 | H11: =(D11*E11)/(D11*F11) -> #DIV/0! | I11: =IFERROR(VLOOKUP(A11,'Master Modelo'!A:I,3,FALSE),0) -> 0 | J11: =IFERROR(VLOOKUP(A11,'Master Modelo'!A:I,5,FALSE),0) -> 0 | K11: =IFERROR(VLOOKUP(A11,'Master Modelo'!A:I,6,FALSE),0) -> 0 | L11: =VLOOKUP(A11,'Master Modelo'!A:J,10,FALSE) -> #N/A | M11: =IFERROR(VLOOKUP(A11,'Master Modelo'!A:I,4,FALSE),0) -> 0 | P11: =D11*F11 -> 0 | Q11: =D11*G11 -> 0 | R11: =D11*E11*'Entrada e Saida'!$K$8 -> 0 | S11: ='Entrada e Saida'!$H$21*'Entrada e Saida'!$K$8*(P11/(SUM(P:P))) -> #DIV/0! | T11: ='Entrada e Saida'!$H$21*'Entrada e Saida'!$K$8*(Q11/(SUM(Q:Q))) -> #DIV/0! | U11: ='Entrada e Saida'!$H$22*(P11/(SUM(P:P))) -> #DIV/0! | V11: ='Entrada e Saida'!$H$22*(Q11/(SUM(Q:Q))) -> #DIV/0! | W11: =R11+S11+U11 -> #DIV/0! | X11: ='Entrada e Saida'!$H$26*(IF('Entrada e Saida'!$H$15="PESO",(P11/(SUM(P:P))),(Q11/(SUM(Q:Q))))) -> #DIV/0! | Y11: ='Entrada e Saida'!$H$27*(IF('Entrada e Saida'!$H$15="PESO",(P11/(SUM(P:P))),(Q11/(SUM(Q:Q))))) -> #DIV/0! | Z11: ='Entrada e Saida'!$H$28*(IF('Entrada e Saida'!$H$15="PESO",(P11/(SUM(P:P))),(Q11/(SUM(Q:Q))))) -> #DIV/0! | AA11: =X11+Y11+Z11 -> #DIV/0! | AB11: =W11*I11 -> #DIV/0! | AC11: =W11*J11 -> #DIV/0! | AD11: =W11*K11 -> #DIV/0! | AE11: =(W11+AB11)*M11 -> #DIV/0! | AF11: =IFERROR(D11*F11*L11*'Entrada e Saida'!$K$8,0) -> 0 | AG11: =((W11+AA11+AB11+AC11+AD11+AE11+AF11)/(1-'Entrada e Saida'!$G$65))*'Entrada e Saida'!$I$66 -> #DIV/0! | AH11: =SUM(AB11:AG11) -> #DIV/0! | AI11: ='Entrada e Saida'!$K$51*(IF('Entrada e Saida'!$H$15="PESO",(P11/(SUM(P:P))),(Q11/(SUM(Q:Q))))) -> #DIV/0! | AJ11: =(('Entrada e Saida'!$K$10-'Entrada e Saida'!$K$8)*E11*D11) -> 0 | AK11: =IF('Entrada e Saida'!$H$15="PESO",W11+AA11+AH11+AI11+AJ11,W11+AA11+AH11+AI11+AJ11-S11+T11-U11+V11) -> #DIV/0! | AL11: =IF('Entrada e Saida'!$H$12="REAL",AC11,0) -> #DIV/0! | AM11: =IF('Entrada e Saida'!$H$12="REAL",AD11,0) -> #DIV/0! | AN11: =IF('Entrada e Saida'!$H$13= "NÃO",AE11,0) -> #DIV/0! | AO11: =AG11 -> #DIV/0! | AP11: =AK11-SUM(AL11:AO11) -> #DIV/0! | AQ11: =IF('Entrada e Saida'!$H$11="TRADING",AU11*'Custo Resumido'!D11,0) -> #DIV/0! | AR11: =IF('Entrada e Saida'!$H$11="TRADING",AU11*'Entrada e Saida'!$G$63,0) -> #DIV/0! | AS11: =IF('Entrada e Saida'!$H$11="TRADING",AU11*'Entrada e Saida'!$G$64,0) -> #DIV/0! | AT11: =IF('Entrada e Saida'!$H$11="TRADING",AU11*'Entrada e Saida'!$G$65,0) -> #DIV/0! | AU11: =IF('Entrada e Saida'!$H$11="TRADING",AP11/(1-(SUM('Entrada e Saida'!$G$63:$G$65)+'Custo Resumido'!D11)),0) -> #DIV/0! | AV11: =IF('Entrada e Saida'!$H$13="NÃO",AU11*M11,0) -> #DIV/0! | AW11: =AU11+AV11 -> #DIV/0! | AX11: ='Entrada e Saida'!$G$74*AU11 -> #DIV/0! | AY11: =AW11-AX11 -> #DIV/0! | AZ11: =AQ11+('Entrada e Saida'!$G$65-'Entrada e Saida'!$I$65)*AU11-AX11 -> #DIV/0! | BA11: =IF('Entrada e Saida'!$H$12="REAL",AZ11*'Entrada e Saida'!$G$81,AU11*'Entrada e Saida'!$G$81) -> #DIV/0! | BB11: =IF('Entrada e Saida'!$H$12="REAL",AZ11*'Entrada e Saida'!$G$82,AU11*'Entrada e Saida'!$G$82) -> #DIV/0! | BC11: =AZ11-BA11-BB11 -> #DIV/0! | BD11: =IF('Entrada e Saida'!$H$11="TRADING",AW11/D11,AK11/D11) -> #DIV/0! | BE11: =AX11/D11 -> #DIV/0! | BF11: =BD11-BE11 -> #DIV/0! | BG11: =IF('Entrada e Saida'!$H$11="TRADING",AV11/D11,AN11/D11) -> #DIV/0! | BH11: =IF('Entrada e Saida'!$H$11="TRADING",IF('Entrada e Saida'!$H$12="REAL",AR11/D11,0),AL11/D11) -> #DIV/0! | BI11: =IF('Entrada e Saida'!$H$11="TRADING",IF('Entrada e Saida'!$H$12="REAL",AS11/D11,0),AM11/D11) -> #DIV/0! | BJ11: =IF('Entrada e Saida'!$H$11="TRADING",AT11/D11,AO11/D11) -> #DIV/0! | BK11: =BF11-SUM(BG11:BJ11) -> #DIV/0! | BL11: =IF(O11>0,IFERROR(IF('Entrada e Saida'!$H$11="DIRETA",0,(IF('Entrada e Saida'!$H$14="P.JURIDICA",(BD11*(1+O11)*N11)-((BD11/(1+M11))*'Entrada e Saida'!$G$65),((Produtos!N11-'Entrada e Saida'!$G$65)*Produtos!BD11)))),0),0) -> 0 | BM11: =BF11+BL11 -> #DIV/0!
B12: =VLOOKUP(A12,'Master Modelo'!A:I,7,FALSE) -> #N/A | C12: =VLOOKUP(A12,'Master Modelo'!A:I,2,FALSE) -> #N/A | E12: =IFERROR(VLOOKUP(A12,'Master Modelo'!A:I,9,FALSE),0) -> 0 | F12: =IFERROR(VLOOKUP(A12,'Master Modelo'!A:I,8,FALSE),0) -> 0 | G12: =IFERROR(VLOOKUP(A12,'Master Modelo'!A:K,11,FALSE),0) -> 0 | H12: =(D12*E12)/(D12*F12) -> #DIV/0! | I12: =IFERROR(VLOOKUP(A12,'Master Modelo'!A:I,3,FALSE),0) -> 0 | J12: =IFERROR(VLOOKUP(A12,'Master Modelo'!A:I,5,FALSE),0) -> 0 | K12: =IFERROR(VLOOKUP(A12,'Master Modelo'!A:I,6,FALSE),0) -> 0 | L12: =VLOOKUP(A12,'Master Modelo'!A:J,10,FALSE) -> #N/A | M12: =IFERROR(VLOOKUP(A12,'Master Modelo'!A:I,4,FALSE),0) -> 0 | P12: =D12*F12 -> 0 | Q12: =D12*G12 -> 0 | R12: =D12*E12*'Entrada e Saida'!$K$8 -> 0 | S12: ='Entrada e Saida'!$H$21*'Entrada e Saida'!$K$8*(P12/(SUM(P:P))) -> #DIV/0! | T12: ='Entrada e Saida'!$H$21*'Entrada e Saida'!$K$8*(Q12/(SUM(Q:Q))) -> #DIV/0! | U12: ='Entrada e Saida'!$H$22*(P12/(SUM(P:P))) -> #DIV/0! | V12: ='Entrada e Saida'!$H$22*(Q12/(SUM(Q:Q))) -> #DIV/0! | W12: =R12+S12+U12 -> #DIV/0! | X12: ='Entrada e Saida'!$H$26*(IF('Entrada e Saida'!$H$15="PESO",(P12/(SUM(P:P))),(Q12/(SUM(Q:Q))))) -> #DIV/0! | Y12: ='Entrada e Saida'!$H$27*(IF('Entrada e Saida'!$H$15="PESO",(P12/(SUM(P:P))),(Q12/(SUM(Q:Q))))) -> #DIV/0! | Z12: ='Entrada e Saida'!$H$28*(IF('Entrada e Saida'!$H$15="PESO",(P12/(SUM(P:P))),(Q12/(SUM(Q:Q))))) -> #DIV/0! | AA12: =X12+Y12+Z12 -> #DIV/0! | AB12: =W12*I12 -> #DIV/0! | AC12: =W12*J12 -> #DIV/0! | AD12: =W12*K12 -> #DIV/0! | AE12: =(W12+AB12)*M12 -> #DIV/0! | AF12: =IFERROR(D12*F12*L12*'Entrada e Saida'!$K$8,0) -> 0 | AG12: =((W12+AA12+AB12+AC12+AD12+AE12+AF12)/(1-'Entrada e Saida'!$G$65))*'Entrada e Saida'!$I$66 -> #DIV/0! | AH12: =SUM(AB12:AG12) -> #DIV/0! | AI12: ='Entrada e Saida'!$K$51*(IF('Entrada e Saida'!$H$15="PESO",(P12/(SUM(P:P))),(Q12/(SUM(Q:Q))))) -> #DIV/0! | AJ12: =(('Entrada e Saida'!$K$10-'Entrada e Saida'!$K$8)*E12*D12) -> 0 | AK12: =IF('Entrada e Saida'!$H$15="PESO",W12+AA12+AH12+AI12+AJ12,W12+AA12+AH12+AI12+AJ12-S12+T12-U12+V12) -> #DIV/0! | AL12: =IF('Entrada e Saida'!$H$12="REAL",AC12,0) -> #DIV/0! | AM12: =IF('Entrada e Saida'!$H$12="REAL",AD12,0) -> #DIV/0! | AN12: =IF('Entrada e Saida'!$H$13= "NÃO",AE12,0) -> #DIV/0! | AO12: =AG12 -> #DIV/0! | AP12: =AK12-SUM(AL12:AO12) -> #DIV/0! | AQ12: =IF('Entrada e Saida'!$H$11="TRADING",AU12*'Custo Resumido'!D12,0) -> #DIV/0! | AR12: =IF('Entrada e Saida'!$H$11="TRADING",AU12*'Entrada e Saida'!$G$63,0) -> #DIV/0! | AS12: =IF('Entrada e Saida'!$H$11="TRADING",AU12*'Entrada e Saida'!$G$64,0) -> #DIV/0! | AT12: =IF('Entrada e Saida'!$H$11="TRADING",AU12*'Entrada e Saida'!$G$65,0) -> #DIV/0! | AU12: =IF('Entrada e Saida'!$H$11="TRADING",AP12/(1-(SUM('Entrada e Saida'!$G$63:$G$65)+'Custo Resumido'!D12)),0) -> #DIV/0! | AV12: =IF('Entrada e Saida'!$H$13="NÃO",AU12*M12,0) -> #DIV/0! | AW12: =AU12+AV12 -> #DIV/0! | AX12: ='Entrada e Saida'!$G$74*AU12 -> #DIV/0! | AY12: =AW12-AX12 -> #DIV/0! | AZ12: =AQ12+('Entrada e Saida'!$G$65-'Entrada e Saida'!$I$65)*AU12-AX12 -> #DIV/0! | BA12: =IF('Entrada e Saida'!$H$12="REAL",AZ12*'Entrada e Saida'!$G$81,AU12*'Entrada e Saida'!$G$81) -> #DIV/0! | BB12: =IF('Entrada e Saida'!$H$12="REAL",AZ12*'Entrada e Saida'!$G$82,AU12*'Entrada e Saida'!$G$82) -> #DIV/0! | BC12: =AZ12-BA12-BB12 -> #DIV/0! | BD12: =IF('Entrada e Saida'!$H$11="TRADING",AW12/D12,AK12/D12) -> #DIV/0! | BE12: =AX12/D12 -> #DIV/0! | BF12: =BD12-BE12 -> #DIV/0! | BG12: =IF('Entrada e Saida'!$H$11="TRADING",AV12/D12,AN12/D12) -> #DIV/0! | BH12: =IF('Entrada e Saida'!$H$11="TRADING",IF('Entrada e Saida'!$H$12="REAL",AR12/D12,0),AL12/D12) -> #DIV/0! | BI12: =IF('Entrada e Saida'!$H$11="TRADING",IF('Entrada e Saida'!$H$12="REAL",AS12/D12,0),AM12/D12) -> #DIV/0! | BJ12: =IF('Entrada e Saida'!$H$11="TRADING",AT12/D12,AO12/D12) -> #DIV/0! | BK12: =BF12-SUM(BG12:BJ12) -> #DIV/0! | BL12: =IF(O12>0,IFERROR(IF('Entrada e Saida'!$H$11="DIRETA",0,(IF('Entrada e Saida'!$H$14="P.JURIDICA",(BD12*(1+O12)*N12)-((BD12/(1+M12))*'Entrada e Saida'!$G$65),((Produtos!N12-'Entrada e Saida'!$G$65)*Produtos!BD12)))),0),0) -> 0 | BM12: =BF12+BL12 -> #DIV/0!
B13: =VLOOKUP(A13,'Master Modelo'!A:I,7,FALSE) -> #N/A | C13: =VLOOKUP(A13,'Master Modelo'!A:I,2,FALSE) -> #N/A | E13: =IFERROR(VLOOKUP(A13,'Master Modelo'!A:I,9,FALSE),0) -> 0 | F13: =IFERROR(VLOOKUP(A13,'Master Modelo'!A:I,8,FALSE),0) -> 0 | G13: =IFERROR(VLOOKUP(A13,'Master Modelo'!A:K,11,FALSE),0) -> 0 | H13: =(D13*E13)/(D13*F13) -> #DIV/0! | I13: =IFERROR(VLOOKUP(A13,'Master Modelo'!A:I,3,FALSE),0) -> 0 | J13: =IFERROR(VLOOKUP(A13,'Master Modelo'!A:I,5,FALSE),0) -> 0 | K13: =IFERROR(VLOOKUP(A13,'Master Modelo'!A:I,6,FALSE),0) -> 0 | L13: =VLOOKUP(A13,'Master Modelo'!A:J,10,FALSE) -> #N/A | M13: =IFERROR(VLOOKUP(A13,'Master Modelo'!A:I,4,FALSE),0) -> 0 | P13: =D13*F13 -> 0 | Q13: =D13*G13 -> 0 | R13: =D13*E13*'Entrada e Saida'!$K$8 -> 0 | S13: ='Entrada e Saida'!$H$21*'Entrada e Saida'!$K$8*(P13/(SUM(P:P))) -> #DIV/0! | T13: ='Entrada e Saida'!$H$21*'Entrada e Saida'!$K$8*(Q13/(SUM(Q:Q))) -> #DIV/0! | U13: ='Entrada e Saida'!$H$22*(P13/(SUM(P:P))) -> #DIV/0! | V13: ='Entrada e Saida'!$H$22*(Q13/(SUM(Q:Q))) -> #DIV/0! | W13: =R13+S13+U13 -> #DIV/0! | X13: ='Entrada e Saida'!$H$26*(IF('Entrada e Saida'!$H$15="PESO",(P13/(SUM(P:P))),(Q13/(SUM(Q:Q))))) -> #DIV/0! | Y13: ='Entrada e Saida'!$H$27*(IF('Entrada e Saida'!$H$15="PESO",(P13/(SUM(P:P))),(Q13/(SUM(Q:Q))))) -> #DIV/0! | Z13: ='Entrada e Saida'!$H$28*(IF('Entrada e Saida'!$H$15="PESO",(P13/(SUM(P:P))),(Q13/(SUM(Q:Q))))) -> #DIV/0! | AA13: =X13+Y13+Z13 -> #DIV/0! | AB13: =W13*I13 -> #DIV/0! | AC13: =W13*J13 -> #DIV/0! | AD13: =W13*K13 -> #DIV/0! | AE13: =(W13+AB13)*M13 -> #DIV/0! | AF13: =IFERROR(D13*F13*L13*'Entrada e Saida'!$K$8,0) -> 0 | AG13: =((W13+AA13+AB13+AC13+AD13+AE13+AF13)/(1-'Entrada e Saida'!$G$65))*'Entrada e Saida'!$I$66 -> #DIV/0! | AH13: =SUM(AB13:AG13) -> #DIV/0! | AI13: ='Entrada e Saida'!$K$51*(IF('Entrada e Saida'!$H$15="PESO",(P13/(SUM(P:P))),(Q13/(SUM(Q:Q))))) -> #DIV/0! | AJ13: =(('Entrada e Saida'!$K$10-'Entrada e Saida'!$K$8)*E13*D13) -> 0 | AK13: =IF('Entrada e Saida'!$H$15="PESO",W13+AA13+AH13+AI13+AJ13,W13+AA13+AH13+AI13+AJ13-S13+T13-U13+V13) -> #DIV/0! | AL13: =IF('Entrada e Saida'!$H$12="REAL",AC13,0) -> #DIV/0! | AM13: =IF('Entrada e Saida'!$H$12="REAL",AD13,0) -> #DIV/0! | AN13: =IF('Entrada e Saida'!$H$13= "NÃO",AE13,0) -> #DIV/0! | AO13: =AG13 -> #DIV/0! | AP13: =AK13-SUM(AL13:AO13) -> #DIV/0! | AQ13: =IF('Entrada e Saida'!$H$11="TRADING",AU13*'Custo Resumido'!D13,0) -> #DIV/0! | AR13: =IF('Entrada e Saida'!$H$11="TRADING",AU13*'Entrada e Saida'!$G$63,0) -> #DIV/0! | AS13: =IF('Entrada e Saida'!$H$11="TRADING",AU13*'Entrada e Saida'!$G$64,0) -> #DIV/0! | AT13: =IF('Entrada e Saida'!$H$11="TRADING",AU13*'Entrada e Saida'!$G$65,0) -> #DIV/0! | AU13: =IF('Entrada e Saida'!$H$11="TRADING",AP13/(1-(SUM('Entrada e Saida'!$G$63:$G$65)+'Custo Resumido'!D13)),0) -> #DIV/0! | AV13: =IF('Entrada e Saida'!$H$13="NÃO",AU13*M13,0) -> #DIV/0! | AW13: =AU13+AV13 -> #DIV/0! | AX13: ='Entrada e Saida'!$G$74*AU13 -> #DIV/0! | AY13: =AW13-AX13 -> #DIV/0! | AZ13: =AQ13+('Entrada e Saida'!$G$65-'Entrada e Saida'!$I$65)*AU13-AX13 -> #DIV/0! | BA13: =IF('Entrada e Saida'!$H$12="REAL",AZ13*'Entrada e Saida'!$G$81,AU13*'Entrada e Saida'!$G$81) -> #DIV/0! | BB13: =IF('Entrada e Saida'!$H$12="REAL",AZ13*'Entrada e Saida'!$G$82,AU13*'Entrada e Saida'!$G$82) -> #DIV/0! | BC13: =AZ13-BA13-BB13 -> #DIV/0! | BD13: =IF('Entrada e Saida'!$H$11="TRADING",AW13/D13,AK13/D13) -> #DIV/0! | BE13: =AX13/D13 -> #DIV/0! | BF13: =BD13-BE13 -> #DIV/0! | BG13: =IF('Entrada e Saida'!$H$11="TRADING",AV13/D13,AN13/D13) -> #DIV/0! | BH13: =IF('Entrada e Saida'!$H$11="TRADING",IF('Entrada e Saida'!$H$12="REAL",AR13/D13,0),AL13/D13) -> #DIV/0! | BI13: =IF('Entrada e Saida'!$H$11="TRADING",IF('Entrada e Saida'!$H$12="REAL",AS13/D13,0),AM13/D13) -> #DIV/0! | BJ13: =IF('Entrada e Saida'!$H$11="TRADING",AT13/D13,AO13/D13) -> #DIV/0! | BK13: =BF13-SUM(BG13:BJ13) -> #DIV/0! | BL13: =IF(O13>0,IFERROR(IF('Entrada e Saida'!$H$11="DIRETA",0,(IF('Entrada e Saida'!$H$14="P.JURIDICA",(BD13*(1+O13)*N13)-((BD13/(1+M13))*'Entrada e Saida'!$G$65),((Produtos!N13-'Entrada e Saida'!$G$65)*Produtos!BD13)))),0),0) -> 0 | BM13: =BF13+BL13 -> #DIV/0!
B14: =VLOOKUP(A14,'Master Modelo'!A:I,7,FALSE) -> #N/A | C14: =VLOOKUP(A14,'Master Modelo'!A:I,2,FALSE) -> #N/A | E14: =IFERROR(VLOOKUP(A14,'Master Modelo'!A:I,9,FALSE),0) -> 0 | F14: =IFERROR(VLOOKUP(A14,'Master Modelo'!A:I,8,FALSE),0) -> 0 | G14: =IFERROR(VLOOKUP(A14,'Master Modelo'!A:K,11,FALSE),0) -> 0 | H14: =(D14*E14)/(D14*F14) -> #DIV/0! | I14: =IFERROR(VLOOKUP(A14,'Master Modelo'!A:I,3,FALSE),0) -> 0 | J14: =IFERROR(VLOOKUP(A14,'Master Modelo'!A:I,5,FALSE),0) -> 0 | K14: =IFERROR(VLOOKUP(A14,'Master Modelo'!A:I,6,FALSE),0) -> 0 | L14: =VLOOKUP(A14,'Master Modelo'!A:J,10,FALSE) -> #N/A | M14: =IFERROR(VLOOKUP(A14,'Master Modelo'!A:I,4,FALSE),0) -> 0 | P14: =D14*F14 -> 0 | Q14: =D14*G14 -> 0 | R14: =D14*E14*'Entrada e Saida'!$K$8 -> 0 | S14: ='Entrada e Saida'!$H$21*'Entrada e Saida'!$K$8*(P14/(SUM(P:P))) -> #DIV/0! | T14: ='Entrada e Saida'!$H$21*'Entrada e Saida'!$K$8*(Q14/(SUM(Q:Q))) -> #DIV/0! | U14: ='Entrada e Saida'!$H$22*(P14/(SUM(P:P))) -> #DIV/0! | V14: ='Entrada e Saida'!$H$22*(Q14/(SUM(Q:Q))) -> #DIV/0! | W14: =R14+S14+U14 -> #DIV/0! | X14: ='Entrada e Saida'!$H$26*(IF('Entrada e Saida'!$H$15="PESO",(P14/(SUM(P:P))),(Q14/(SUM(Q:Q))))) -> #DIV/0! | Y14: ='Entrada e Saida'!$H$27*(IF('Entrada e Saida'!$H$15="PESO",(P14/(SUM(P:P))),(Q14/(SUM(Q:Q))))) -> #DIV/0! | Z14: ='Entrada e Saida'!$H$28*(IF('Entrada e Saida'!$H$15="PESO",(P14/(SUM(P:P))),(Q14/(SUM(Q:Q))))) -> #DIV/0! | AA14: =X14+Y14+Z14 -> #DIV/0! | AB14: =W14*I14 -> #DIV/0! | AC14: =W14*J14 -> #DIV/0! | AD14: =W14*K14 -> #DIV/0! | AE14: =(W14+AB14)*M14 -> #DIV/0! | AF14: =IFERROR(D14*F14*L14*'Entrada e Saida'!$K$8,0) -> 0 | AG14: =((W14+AA14+AB14+AC14+AD14+AE14+AF14)/(1-'Entrada e Saida'!$G$65))*'Entrada e Saida'!$I$66 -> #DIV/0! | AH14: =SUM(AB14:AG14) -> #DIV/0! | AI14: ='Entrada e Saida'!$K$51*(IF('Entrada e Saida'!$H$15="PESO",(P14/(SUM(P:P))),(Q14/(SUM(Q:Q))))) -> #DIV/0! | AJ14: =(('Entrada e Saida'!$K$10-'Entrada e Saida'!$K$8)*E14*D14) -> 0 | AK14: =IF('Entrada e Saida'!$H$15="PESO",W14+AA14+AH14+AI14+AJ14,W14+AA14+AH14+AI14+AJ14-S14+T14-U14+V14) -> #DIV/0! | AL14: =IF('Entrada e Saida'!$H$12="REAL",AC14,0) -> #DIV/0! | AM14: =IF('Entrada e Saida'!$H$12="REAL",AD14,0) -> #DIV/0! | AN14: =IF('Entrada e Saida'!$H$13= "NÃO",AE14,0) -> #DIV/0! | AO14: =AG14 -> #DIV/0! | AP14: =AK14-SUM(AL14:AO14) -> #DIV/0! | AQ14: =IF('Entrada e Saida'!$H$11="TRADING",AU14*'Custo Resumido'!D14,0) -> #DIV/0! | AR14: =IF('Entrada e Saida'!$H$11="TRADING",AU14*'Entrada e Saida'!$G$63,0) -> #DIV/0! | AS14: =IF('Entrada e Saida'!$H$11="TRADING",AU14*'Entrada e Saida'!$G$64,0) -> #DIV/0! | AT14: =IF('Entrada e Saida'!$H$11="TRADING",AU14*'Entrada e Saida'!$G$65,0) -> #DIV/0! | AU14: =IF('Entrada e Saida'!$H$11="TRADING",AP14/(1-(SUM('Entrada e Saida'!$G$63:$G$65)+'Custo Resumido'!D14)),0) -> #DIV/0! | AV14: =IF('Entrada e Saida'!$H$13="NÃO",AU14*M14,0) -> #DIV/0! | AW14: =AU14+AV14 -> #DIV/0! | AX14: ='Entrada e Saida'!$G$74*AU14 -> #DIV/0! | AY14: =AW14-AX14 -> #DIV/0! | AZ14: =AQ14+('Entrada e Saida'!$G$65-'Entrada e Saida'!$I$65)*AU14-AX14 -> #DIV/0! | BA14: =IF('Entrada e Saida'!$H$12="REAL",AZ14*'Entrada e Saida'!$G$81,AU14*'Entrada e Saida'!$G$81) -> #DIV/0! | BB14: =IF('Entrada e Saida'!$H$12="REAL",AZ14*'Entrada e Saida'!$G$82,AU14*'Entrada e Saida'!$G$82) -> #DIV/0! | BC14: =AZ14-BA14-BB14 -> #DIV/0! | BD14: =IF('Entrada e Saida'!$H$11="TRADING",AW14/D14,AK14/D14) -> #DIV/0! | BE14: =AX14/D14 -> #DIV/0! | BF14: =BD14-BE14 -> #DIV/0! | BG14: =IF('Entrada e Saida'!$H$11="TRADING",AV14/D14,AN14/D14) -> #DIV/0! | BH14: =IF('Entrada e Saida'!$H$11="TRADING",IF('Entrada e Saida'!$H$12="REAL",AR14/D14,0),AL14/D14) -> #DIV/0! | BI14: =IF('Entrada e Saida'!$H$11="TRADING",IF('Entrada e Saida'!$H$12="REAL",AS14/D14,0),AM14/D14) -> #DIV/0! | BJ14: =IF('Entrada e Saida'!$H$11="TRADING",AT14/D14,AO14/D14) -> #DIV/0! | BK14: =BF14-SUM(BG14:BJ14) -> #DIV/0! | BL14: =IF(O14>0,IFERROR(IF('Entrada e Saida'!$H$11="DIRETA",0,(IF('Entrada e Saida'!$H$14="P.JURIDICA",(BD14*(1+O14)*N14)-((BD14/(1+M14))*'Entrada e Saida'!$G$65),((Produtos!N14-'Entrada e Saida'!$G$65)*Produtos!BD14)))),0),0) -> 0 | BM14: =BF14+BL14 -> #DIV/0!
... B96: =VLOOKUP(A96,'Master Modelo'!A:I,7,FALSE) -> #N/A | C96: =VLOOKUP(A96,'Master Modelo'!A:I,2,FALSE) -> #N/A | E96: =IFERROR(VLOOKUP(A96,'Master Modelo'!A:I,9,FALSE),0) -> 0 | F96: =IFERROR(VLOOKUP(A96,'Master Modelo'!A:I,8,FALSE),0) -> 0 | G96: =IFERROR(VLOOKUP(A96,'Master Modelo'!A:K,11,FALSE),0) -> 0 | H96: =(D96*E96)/(D96*F96) -> #DIV/0! | I96: =IFERROR(VLOOKUP(A96,'Master Modelo'!A:I,3,FALSE),0) -> 0 | J96: =IFERROR(VLOOKUP(A96,'Master Modelo'!A:I,5,FALSE),0) -> 0 | K96: =IFERROR(VLOOKUP(A96,'Master Modelo'!A:I,6,FALSE),0) -> 0 | L96: =VLOOKUP(A96,'Master Modelo'!A:J,10,FALSE) -> #N/A | M96: =IFERROR(VLOOKUP(A96,'Master Modelo'!A:I,4,FALSE),0) -> 0 | P96: =D96*F96 -> 0 | Q96: =D96*G96 -> 0 | R96: =D96*E96*'Entrada e Saida'!$K$8 -> 0 | S96: ='Entrada e Saida'!$H$21*'Entrada e Saida'!$K$8*(P96/(SUM(P:P))) -> #DIV/0! | T96: ='Entrada e Saida'!$H$21*'Entrada e Saida'!$K$8*(Q96/(SUM(Q:Q))) -> #DIV/0! | U96: ='Entrada e Saida'!$H$22*(P96/(SUM(P:P))) -> #DIV/0! | V96: ='Entrada e Saida'!$H$22*(Q96/(SUM(Q:Q))) -> #DIV/0! | W96: =R96+S96+U96 -> #DIV/0! | X96: ='Entrada e Saida'!$H$26*(IF('Entrada e Saida'!$H$15="PESO",(P96/(SUM(P:P))),(Q96/(SUM(Q:Q))))) -> #DIV/0! | Y96: ='Entrada e Saida'!$H$27*(IF('Entrada e Saida'!$H$15="PESO",(P96/(SUM(P:P))),(Q96/(SUM(Q:Q))))) -> #DIV/0! | Z96: ='Entrada e Saida'!$H$28*(IF('Entrada e Saida'!$H$15="PESO",(P96/(SUM(P:P))),(Q96/(SUM(Q:Q))))) -> #DIV/0! | AA96: =X96+Y96+Z96 -> #DIV/0! | AB96: =W96*I96 -> #DIV/0! | AC96: =W96*J96 -> #DIV/0! | AD96: =W96*K96 -> #DIV/0! | AE96: =(W96+AB96)*M96 -> #DIV/0! | AF96: =IFERROR(D96*F96*L96*'Entrada e Saida'!$K$8,0) -> 0 | AG96: =((W96+AA96+AB96+AC96+AD96+AE96+AF96)/(1-'Entrada e Saida'!$G$65))*'Entrada e Saida'!$I$66 -> #DIV/0! | AH96: =SUM(AB96:AG96) -> #DIV/0! | AI96: ='Entrada e Saida'!$K$51*(IF('Entrada e Saida'!$H$15="PESO",(P96/(SUM(P:P))),(Q96/(SUM(Q:Q))))) -> #DIV/0! | AJ96: =(('Entrada e Saida'!$K$10-'Entrada e Saida'!$K$8)*E96*D96) -> 0 | AK96: =IF('Entrada e Saida'!$H$15="PESO",W96+AA96+AH96+AI96+AJ96,W96+AA96+AH96+AI96+AJ96-S96+T96-U96+V96) -> #DIV/0! | AL96: =IF('Entrada e Saida'!$H$12="REAL",AC96,0) -> #DIV/0! | AM96: =IF('Entrada e Saida'!$H$12="REAL",AD96,0) -> #DIV/0! | AN96: =IF('Entrada e Saida'!$H$13= "NÃO",AE96,0) -> #DIV/0! | AO96: =AG96 -> #DIV/0! | AP96: =AK96-SUM(AL96:AO96) -> #DIV/0! | AQ96: =IF('Entrada e Saida'!$H$11="TRADING",AU96*'Custo Resumido'!D96,0) -> #DIV/0! | AR96: =IF('Entrada e Saida'!$H$11="TRADING",AU96*'Entrada e Saida'!$G$63,0) -> #DIV/0! | AS96: =IF('Entrada e Saida'!$H$11="TRADING",AU96*'Entrada e Saida'!$G$64,0) -> #DIV/0! | AT96: =IF('Entrada e Saida'!$H$11="TRADING",AU96*'Entrada e Saida'!$G$65,0) -> #DIV/0! | AU96: =IF('Entrada e Saida'!$H$11="TRADING",AP96/(1-(SUM('Entrada e Saida'!$G$63:$G$65)+'Custo Resumido'!D96)),0) -> #DIV/0! | AV96: =IF('Entrada e Saida'!$H$13="NÃO",AU96*M96,0) -> #DIV/0! | AW96: =AU96+AV96 -> #DIV/0! | AX96: ='Entrada e Saida'!$G$74*AU96 -> #DIV/0! | AY96: =AW96-AX96 -> #DIV/0! | AZ96: =AQ96+('Entrada e Saida'!$G$65-'Entrada e Saida'!$I$65)*AU96-AX96 -> #DIV/0! | BA96: =IF('Entrada e Saida'!$H$12="REAL",AZ96*'Entrada e Saida'!$G$81,AU96*'Entrada e Saida'!$G$81) -> #DIV/0! | BB96: =IF('Entrada e Saida'!$H$12="REAL",AZ96*'Entrada e Saida'!$G$82,AU96*'Entrada e Saida'!$G$82) -> #DIV/0! | BC96: =AZ96-BA96-BB96 -> #DIV/0! | BD96: =IF('Entrada e Saida'!$H$11="TRADING",AW96/D96,AK96/D96) -> #DIV/0! | BE96: =AX96/D96 -> #DIV/0! | BF96: =BD96-BE96 -> #DIV/0! | BG96: =IF('Entrada e Saida'!$H$11="TRADING",AV96/D96,AN96/D96) -> #DIV/0! | BH96: =IF('Entrada e Saida'!$H$11="TRADING",IF('Entrada e Saida'!$H$12="REAL",AR96/D96,0),AL96/D96) -> #DIV/0! | BI96: =IF('Entrada e Saida'!$H$11="TRADING",IF('Entrada e Saida'!$H$12="REAL",AS96/D96,0),AM96/D96) -> #DIV/0! | BJ96: =IF('Entrada e Saida'!$H$11="TRADING",AT96/D96,AO96/D96) -> #DIV/0! | BK96: =BF96-SUM(BG96:BJ96) -> #DIV/0! | BL96: =IF(O96>0,IFERROR(IF('Entrada e Saida'!$H$11="DIRETA",0,(IF('Entrada e Saida'!$H$14="P.JURIDICA",(BD96*(1+O96)*N96)-((BD96/(1+M96))*'Entrada e Saida'!$G$65),((Produtos!N96-'Entrada e Saida'!$G$65)*Produtos!BD96)))),0),0) -> 0 | BM96: =BF96+BL96 -> #DIV/0!
